Workbook

Sheet Summary and Assumptions
B1: =D9 -> Fund Name | K1: Model Key
B2: Portfolio Model | K2: Hardcoded assumption, can edit
K3: Formula, do not edit
K4: Pull from another tab, do not edit
K5: Pull from another tab, can be updated
A6: x | B6: Fund Characteristics
C9: Name | D9: Fund Name | F9: # of target initial investments: | G9: =D102 -> 35
C10: Start Date | D10: 44197
C11: Fund Size | D11: 100000000 | F11: Deals to date: | G11: =SUM(Portfolio!R158:V158) -> 0
C12: End date of intl invt period | D12: {=INDEX(Portfolio!F7:F156,(MATCH(D102,Portfolio!C7:C156,0)+1))} -> 45422 | F12: Intl Invst. to date: | G12: =Portfolio!O158 -> 0
C13: Today's Date | D13: =TODAY() -> 43958
C15: Fund to Date | D15: Seed | E15: Ext | F15: Series A | G15: Series B | H15: Series C | I15: All Rounds
C16: Invested | D16: =Portfolio!R159 -> 0 | E16: =Portfolio!S159 -> 0 | F16: =Portfolio!T159 -> 0 | G16: =Portfolio!U159 -> 0 | H16: =Portfolio!V159 -> 0 | I16: =IFERROR(SUM(D16:H16),"NA") -> 0
C17: Returned | D17: =Portfolio!R160 -> 0 | E17: =Portfolio!S160 -> 0 | F17: =Portfolio!T160 -> 0 | G17: =Portfolio!U160 -> 0 | H17: =Portfolio!V160 -> 0 | I17: =IFERROR(SUM(D17:H17),"NA") -> 0
C18: Rate | D18: =IFERROR(D17/D16,"NA") -> NA | E18: =IFERROR(E17/E16,"NA") -> NA | F18: =IFERROR(F17/F16,"NA") -> NA | G18: =IFERROR(G17/G16,"NA") -> NA | H18: =IFERROR(H17/H16,"NA") -> NA | I18: =IFERROR(I17/I16,"NA") -> NA
C19: # of Deals | D19: =Portfolio!R158 -> 0 | E19: =Portfolio!S158 -> 0 | F19: =Portfolio!T158 -> 0 | G19: =Portfolio!U158 -> 0 | H19: =Portfolio!V158 -> 0 | I19: =IFERROR(SUM(D19:H19),"NA") -> 0
C20: Average Deal Size | D20: =Portfolio!R157 -> NA | E20: =Portfolio!S157 -> NA | F20: =Portfolio!T157 -> NA | G20: =Portfolio!U157 -> NA | H20: =Portfolio!V157 -> NA | I20: =IFERROR(SUM(D20:H20),"NA") -> 0
C21: Total Conversion Rate | E21: =IFERROR(E19/$D$19,"NA") -> NA | F21: =IFERROR(F19/$D$19,"NA") -> NA | G21: =IFERROR(G19/$D$19,"NA") -> NA | H21: =IFERROR(H19/$D$19,"NA") -> NA
C22: Conversion Rate excl deals in last 2yrs | E22: =Portfolio!R165 -> NA | F22: =Portfolio!S165 -> NA | G22: =Portfolio!T165 -> NA | H22: =Portfolio!U165 -> NA
A25: x | B25: Summary
D28: Initial Invsts | E28: Follow-On Invsts | F28: Total Investment | G28: Seed Invsts | H28: Ext Invsts | I28: Series A Invsts | J28: Series B Invsts | K28: Series C Invsts | L28: Mgmt Fees | M28: Other Expenses | N28: Total Expenses | O28: Recycled Returns | P28: Total Returns | Q28: Distributions
C29: Actual to Date | D29: =Portfolio!R159 -> 0 | E29: =SUM(Portfolio!S159:V159) -> 0 | F29: =SUM(E29,D29) -> 0 | G29: =D16 -> 0 | H29: =E16 -> 0 | I29: =F16 -> 0 | J29: =G16 -> 0 | K29: =H16 -> 0 | L29: =SUMIF(Model!D4:BS4,"<="&TODAY(),Model!D121:BS121) -> 0 | M29: =SUMPRODUCT((Model!$D$4:$BS$4<=$D$13)*(Model!D115:BS120)) -> 0 | N29: =SUM(M29,L29) -> 0 | O29: =P29-Q29 -> 0 | P29: =Portfolio!W159 -> 0 | Q29: =SUMIF(Model!D4:BS4,"<="&TODAY(),Model!D138:BS138) -> 0
C30: Forecasted | D30: =Portfolio!AC159 -> 43750000 | E30: =SUM(Portfolio!AD159:AG159) -> 63000000 | F30: =SUM(E30,D30) -> 106750000 | G30: =Portfolio!AC159 -> 43750000 | H30: =Portfolio!AD159 -> 3937500 | I30: =Portfolio!AE159 -> 32812500 | J30: =Portfolio!AF159 -> 26250000 | K30: =Portfolio!AG159 -> 0 | L30: =SUMIF(Model!D4:BS4,">"&TODAY(),Model!D121:BS121) -> 22125000 | M30: =SUMPRODUCT((Model!$D$4:$BS$4>$D$13)*(Model!D115:BS120)) -> 1100000 | N30: =SUM(M30,L30) -> 23225000 | O30: =P30-Q30 -> 0 | P30: =Portfolio!AH159 -> 0 | Q30: =SUMIF(Model!D4:BS4,">"&TODAY(),Model!D138:BS138) -> 0
C31: Total (Actual + Forecast) | D31: =SUM(D29:D30) -> 43750000 | E31: =SUM(E29:E30) -> 63000000 | F31: =SUM(E31,D31) -> 106750000 | G31: =SUM(G29:G30) -> 43750000 | H31: =SUM(H29:H30) -> 3937500 | I31: =SUM(I29:I30) -> 32812500 | J31: =SUM(J29:J30) -> 26250000 | K31: =SUM(K29:K30) -> 0 | L31: =SUM(L29:L30) -> 22125000 | M31: =SUM(M29:M30) -> 1100000 | N31: =SUM(M31,L31) -> 23225000 | O31: =SUM(O29:O30) -> 0 | P31: =SUM(P29:P30) -> 0 | Q31: =SUM(Q29:Q30) -> 0
C32: As % of Total Fund | D32: =D31/$D$11 -> 0.4375 | E32: =E31/$D$11 -> 0.63 | F32: =F31/$D$11 -> 1.0675 | G32: =G31/$D$11 -> 0.4375 | H32: =H31/$D$11 -> 0.039375 | I32: =I31/$D$11 -> 0.328125 | J32: =J31/$D$11 -> 0.2625 | K32: =K31/$D$11 -> 0 | ... Q32: =Q31/$D$11 -> 0
C33: As % of Total Invested | D33: =D31/$F$31 -> 0.40983607 | E33: =E31/$F$31 -> 0.59016393 | F33: =F31/$F$31 -> 1 | G33: =G31/$F$31 -> 0.40983607 | H33: =H31/$F$31 -> 0.036885246 | I33: =I31/$F$31 -> 0.30737705 | J33: =J31/$F$31 -> 0.24590164 | K33: =K31/$F$31 -> 0 | ... Q33: =Q31/$F$31 -> 0
D36: Cash Flow Model | K36: Investable Capital Model
D37: Max out date | E37: {=IFERROR(INDEX(Model!D4:BS4,MATCH(TRUE,Model!D140:BS140<0,0)),"No Max-out Date")} -> 45838 | K37: Max out date | L37: {=IFERROR(INDEX(Model!D4:BS4,MATCH(TRUE,Model!D142:BS142<0,0)),"No Max-out Day")} -> 45657
D38: Months remaining | E38: =IFERROR(IF($D$13>$D$10,DATEDIF($D$13,E37,"m"),DATEDIF($D$10,E37,"m")),"NA") -> 53 | K38: Months remaining | L38: =IFERROR(IF($D$13>$D$10,DATEDIF($D$13,L37,"m"),DATEDIF($D$10,L37,"m")),"NA") -> 47
D39: Qs remaining | E39: =IFERROR(IF($D$13>$D$10,FLOOR(((YEAR(E37)*12+MONTH(E37))-(YEAR($D$13)*12+MONTH($D$13)))/3,1),FLOOR(((YEAR(E37)*12+MONTH(E37))-(YEAR($D$10)*12+MONTH($D$10)))/3,1)),"NA") -> 17 | K39: Qs remaining | L39: =IFERROR(IF($D$13>$D$10,FLOOR(((YEAR(L37)*12+MONTH(L37))-(YEAR($D$13)*12+MONTH($D$13)))/3,1),FLOOR(((YEAR(L37)*12+MONTH(L37))-(YEAR($D$10)*12+MONTH($D$10)))/3,1)),"NA") -> 15
D40: Recycled at max-out | E40: {=IFERROR(INDEX(Model!$D$146:$AU$146,(MATCH(E37,Model!$D$4:$AU$4,0))),"No Max-out")} -> 0.88525 | K40: Recycled at max-out | L40: {=IFERROR(INDEX(Model!$D$146:$AU$146,(MATCH(L37,Model!$D$4:$AU$4,0))),"No Max-out")} -> 0.79525
D41: Target recycling hit | E41: =EDATE(INDEX(Model!$D$4:$AU$4,(MATCH($D$105,Model!$D$146:$AU$146))),3) -> 48304 | K41: Target recycling hit | L41: {=EDATE(INDEX(Model!$D$4:$AU$4,(MATCH($D$105,Model!$D$146:$AU$146))),3)} -> 48304
A65: x | B65: Return Scenarios
D69: Bear Case Scenario | J69: Base Case Scenario | Q69: Bull Case Scenario
D70: Max out date | E70: {=IFERROR(INDEX(Model!D4:BS4,MATCH(TRUE,Model!D173:BS173<0,0)),"No Max-out")} -> 45838 | J70: Max out date | K70: {=IFERROR(INDEX(Model!J4:BY4,MATCH(TRUE,Model!J200:BY200<0,0)),"No Max-out")} -> 45930 | Q70: Max out date | R70: {=IFERROR(INDEX(Model!Q4:CF4,MATCH(TRUE,Model!Q227:CF227<0,0)),"No Max-out")} -> No Max-out
D71: Months remaining | E71: =IFERROR(IF($D$13>$D$10,DATEDIF($D$13,E70,"m"),DATEDIF($D$10,E70,"m")),"NA") -> 53 | J71: Months remaining | K71: =IFERROR(IF($D$13>$D$10,DATEDIF($D$13,K70,"m"),DATEDIF($D$10,K70,"m")),"NA") -> 56 | Q71: Months remaining | R71: =IFERROR(IF($D$13>$D$10,DATEDIF($D$13,R70,"m"),DATEDIF($D$10,R70,"m")),"NA") -> NA
D72: Qs remaining | E72: =IFERROR(IF($D$13>$D$10,FLOOR(((YEAR(E70)*12+MONTH(E70))-(YEAR($D$13)*12+MONTH($D$13)))/3,1),FLOOR(((YEAR(E70)*12+MONTH(E70))-(YEAR($D$10)*12+MONTH($D$10)))/3,1)),"NA") -> 17 | J72: Qs remaining | K72: =IFERROR(IF($D$13>$D$10,FLOOR(((YEAR(K70)*12+MONTH(K70))-(YEAR($D$13)*12+MONTH($D$13)))/3,1),FLOOR(((YEAR(K70)*12+MONTH(K70))-(YEAR($D$10)*12+MONTH($D$10)))/3,1)),"NA") -> 18 | Q72: Qs remaining | R72: =IFERROR(IF($D$13>$D$10,FLOOR(((YEAR(R70)*12+MONTH(R70))-(YEAR($D$13)*12+MONTH($D$13)))/3,1),FLOOR(((YEAR(R70)*12+MONTH(R70))-(YEAR($D$10)*12+MONTH($D$10)))/3,1)),"NA") -> NA
D73: Recycled at max-out | E73: {=IFERROR(INDEX(Model!$D$160:$AU$160,(MATCH(E70,Model!$D$4:$AU$4,0))),"No Max-out")} -> 0.88525 | J73: Recycled at max-out | K73: {=IFERROR(INDEX(Model!$D$187:$AU$187,(MATCH(K70,Model!$D$4:$AU$4,0))),"No Max-out")} -> 0.938125 | Q73: Recycled at max-out | R73: {=IFERROR(INDEX(Model!$D$214:$AU$214,(MATCH(R70,Model!$D$4:$AU$4,0))),"No Max-out")} -> No Max-out
A98: x | B98: Investment Assumptions
C101: Avg Seed investment | D101: 1250000 | J101: Investment Size as % Seed | L101: Current Fund Avg. | N101: Avg Investment in a Company
...

Sheet Portfolio
B1: =Model!B1 -> Fund Name
B2: Portfolio
B3: Today | D3: ='Summary and Assumptions'!D13 -> 43958 | F3: # of Invst. | H3: ='Summary and Assumptions'!D102 -> 35
B4: Start Date | D4: ='Summary and Assumptions'!D10 -> 44197 | F4: Days to add if overdue | H4: 90
O5: Executed Deals | Z5: Forecast Deals
B6: F/E? | C6: Companies | E6: Info | F6: Seed | G6: Ext. | H6: A | I6: B | J6: C | K6: Stage | L6: Returns | O6: =C6 -> Companies | Q6: Intl Inv Date | R6: =F6 -> Seed | S6: =G6 -> Ext. | T6: =H6 -> A | U6: =I6 -> B | V6: =J6 -> C | W6: Returns | X6: Stage | Z6: =O6 -> Companies | AB6: =Q6 -> Intl Inv Date | AC6: =R6 -> Seed | AD6: =S6 -> Ext. | AE6: =T6 -> A | AF6: =U6 -> B | AG6: =V6 -> C | AH6: =W6 -> Returns
B7: F | C7: =G3+1 -> 1 | D7: =IF(C7<=$H$3,"Company"&" "&C7,"") -> Company 1 | E7: FQ End Date | F7: =IFERROR(IF(F8>0,(DATE(YEAR(F8),((INT((MONTH(F8)-1)/3)+1)*3)+1,1)-1),"-"),"NA") -> 44286 | G7: =IFERROR(IF(G8>0,(DATE(YEAR(G8),((INT((MONTH(G8)-1)/3)+1)*3)+1,1)-1),"-"),"NA") -> 44742 | H7: =IFERROR(IF(H8>0,(DATE(YEAR(H8),((INT((MONTH(H8)-1)/3)+1)*3)+1,1)-1),"-"),"NA") -> 44834 | I7: =IFERROR(IF(I8>0,(DATE(YEAR(I8),((INT((MONTH(I8)-1)/3)+1)*3)+1,1)-1),"-"),"NA") -> 45291 | J7: =IFERROR(IF(J8>0,(DATE(YEAR(J8),((INT((MONTH(J8)-1)/3)+1)*3)+1,1)-1),"-"),"NA") -> 45747 | L7: =IFERROR(IF(L8>0,(DATE(YEAR(L8),((INT((MONTH(L8)-1)/3)+1)*3)+1,1)-1),"-"),"") -> 45747 | O7: =IF(F8<=TODAY(),C7,"0") -> 0 | P7: =IF(F8<=TODAY(),D7,"0") -> 0 | Q7: =IF(F8<=TODAY(),F8,"0") -> 0 | R7: =IF(F8<=TODAY(),F9,0) -> 0 | S7: =IF(G8<=TODAY(),G9,0) -> 0 | T7: =IF(H8<=TODAY(),H9,0) -> 0 | U7: =IF(I8<=TODAY(),I9,0) -> 0 | V7: =IF(J8<=TODAY(),J9,0) -> 0 | W7: =IF(L8<=TODAY(),L9,0) -> 0 | X7: =IF(K8<=TODAY(),K9,"-") -> 0 | Z7: =C7 -> 1 | AA7: =D7 -> Company 1 | AB7: =F8 -> 44232 | AC7: =IF(F8>TODAY(),F9,"0") -> 1250000 | AD7: =IF(G8>TODAY(),G9,"0") -> 112500 | AE7: =IF(H8>TODAY(),H9,"0") -> 937500 | AF7: =IF(I8>TODAY(),I9,"0") -> 750000 | AG7: =IF(J8>TODAY(),J9,"0") -> 0 | AH7: =IF(L8>TODAY(),L9,"0") -> 0
E8: Date | F8: =IF(C7<=$H$3,IF((D4+('Summary and Assumptions'!$K$118*7))>$D$3,(D4+('Summary and Assumptions'!$K$118*7)),($D$3+$H$4)),"") -> 44232 | G8: =IF($C7<=$H$3,IF((F8+('Summary and Assumptions'!$K$119*7))>$D$3,(F8+('Summary and Assumptions'!$K$119*7)),($D$3+$H$4)),"") -> 44687 | H8: =IF($C7<=$H$3,IF((F8+('Summary and Assumptions'!$K$120*7))>$D$3,(F8+('Summary and Assumptions'!$K$120*7)),($D$3+$H$4)),"") -> 44757 | I8: =IF($C7<=$H$3,IF((H8+('Summary and Assumptions'!$K$121*7))>$D$3,(H8+('Summary and Assumptions'!$K$121*7)),($D$3+$H$4)),"") -> 45289 | J8: =IF($C7<=$H$3,IF((I8+('Summary and Assumptions'!$K$122*7))>$D$3,(I8+('Summary and Assumptions'!$K$122*7)),($D$3+$H$4)),"") -> 45737 | L8: =IF($C7<=$H$3,IF((J8+('Summary and Assumptions'!$K$123*7))>$D$3,(J8+('Summary and Assumptions'!$K$123*7)),($D$3+$H$4)),"") -> 45737
E9: Amount | F9: =IF(C7<=$H$3,'Summary and Assumptions'!$D$101,"") -> 1250000 | G9: =IF(C7<=$H$3,F9*'Summary and Assumptions'!$K$111*'Summary and Assumptions'!$K$102,"") -> 112500 | H9: =IF(C7<=$H$3,$F9*'Summary and Assumptions'!$K$112*'Summary and Assumptions'!$K$103,"") -> 937500 | I9: =IF(C7<=$H$3,$F9*'Summary and Assumptions'!$K$113*'Summary and Assumptions'!$K$104,"") -> 750000 | J9: =IF(C7<=$H$3,$F9*'Summary and Assumptions'!$K$114*'Summary and Assumptions'!$K$105,"") -> 0 | K9: =IF(AND(J8<=$D$3,J9>0),$J$6,IF(AND(I8<=$D$3,I9>0),$I$6,IF(AND(H8<=$D$3,H9>0),$H$6,IF(AND(G8<=$D$3,G9>0),$G$6,IF(AND(F8<=$D$3,F9>0),$F$6,"0"))))) -> 0 | L9: =IF(C7<=$H$3,SUM($F9:$I9)*(1+'Summary and Assumptions'!$D$103),"") -> 0
B10: F | C10: =C7+1 -> 2 | D10: =IF(C10<=$H$3,"Company"&" "&C10,"") -> Company 2 | E10: FQ End Date | F10: =IFERROR(IF(F11>0,(DATE(YEAR(F11),((INT((MONTH(F11)-1)/3)+1)*3)+1,1)-1),"-"),"NA") -> 44286 | G10: =IFERROR(IF(G11>0,(DATE(YEAR(G11),((INT((MONTH(G11)-1)/3)+1)*3)+1,1)-1),"-"),"NA") -> 44742 | H10: =IFERROR(IF(H11>0,(DATE(YEAR(H11),((INT((MONTH(H11)-1)/3)+1)*3)+1,1)-1),"-"),"NA") -> 44834 | I10: =IFERROR(IF(I11>0,(DATE(YEAR(I11),((INT((MONTH(I11)-1)/3)+1)*3)+1,1)-1),"-"),"NA") -> 45382 | J10: =IFERROR(IF(J11>0,(DATE(YEAR(J11),((INT((MONTH(J11)-1)/3)+1)*3)+1,1)-1),"-"),"NA") -> 45838 | L10: =IFERROR(IF(L11>0,(DATE(YEAR(L11),((INT((MONTH(L11)-1)/3)+1)*3)+1,1)-1),"-"),"") -> 45838 | O10: =IF(F11<=TODAY(),C10,"0") -> 0 | P10: =IF(F11<=TODAY(),D10,"0") -> 0 | Q10: =IF(F11<=TODAY(),F11,"0") -> 0 | R10: =IF(F11<=TODAY(),F12,0) -> 0 | S10: =IF(G11<=TODAY(),G12,0) -> 0 | T10: =IF(H11<=TODAY(),H12,0) -> 0 | U10: =IF(I11<=TODAY(),I12,0) -> 0 | V10: =IF(J11<=TODAY(),J12,0) -> 0 | W10: =IF(L11<=TODAY(),L12,0) -> 0 | X10: =IF(K11<=TODAY(),K12,"-") -> 0 | Z10: =C10 -> 2 | AA10: =D10 -> Company 2 | AB10: =F11 -> 44267 | AC10: =IF(F11>TODAY(),F12,"0") -> 1250000 | AD10: =IF(G11>TODAY(),G12,"0") -> 112500 | AE10: =IF(H11>TODAY(),H12,"0") -> 937500 | AF10: =IF(I11>TODAY(),I12,"0") -> 750000 | AG10: =IF(J11>TODAY(),J12,"0") -> 0 | AH10: =IF(L11>TODAY(),L12,"0") -> 0
E11: Date | F11: =IF(C10<=$H$3,IF((F8+('Summary and Assumptions'!$K$118*7))>$D$3,(F8+('Summary and Assumptions'!$K$118*7)),($D$3+$H$4)),"") -> 44267 | G11: =IF($C10<=$H$3,IF((F11+('Summary and Assumptions'!$K$119*7))>$D$3,(F11+('Summary and Assumptions'!$K$119*7)),($D$3+$H$4)),"") -> 44722 | H11: =IF($C10<=$H$3,IF((F11+('Summary and Assumptions'!$K$120*7))>$D$3,(F11+('Summary and Assumptions'!$K$120*7)),($D$3+$H$4)),"") -> 44792 | I11: =IF($C10<=$H$3,IF((H11+('Summary and Assumptions'!$K$121*7))>$D$3,(H11+('Summary and Assumptions'!$K$121*7)),($D$3+$H$4)),"") -> 45324 | J11: =IF($C10<=$H$3,IF((I11+('Summary and Assumptions'!$K$122*7))>$D$3,(I11+('Summary and Assumptions'!$K$122*7)),($D$3+$H$4)),"") -> 45772 | L11: =IF($C10<=$H$3,IF((J11+('Summary and Assumptions'!$K$123*7))>$D$3,(J11+('Summary and Assumptions'!$K$123*7)),($D$3+$H$4)),"") -> 45772
E12: Amount | F12: =IF(C10<=$H$3,'Summary and Assumptions'!$D$101,"") -> 1250000 | G12: =IF(C10<=$H$3,F12*'Summary and Assumptions'!$K$111*'Summary and Assumptions'!$K$102,"") -> 112500 | H12: =IF(C10<=$H$3,$F12*'Summary and Assumptions'!$K$112*'Summary and Assumptions'!$K$103,"") -> 937500 | I12: =IF(C10<=$H$3,$F12*'Summary and Assumptions'!$K$113*'Summary and Assumptions'!$K$104,"") -> 750000 | J12: =IF(C10<=$H$3,$F12*'Summary and Assumptions'!$K$114*'Summary and Assumptions'!$K$105,"") -> 0 | K12: =IF(AND(J11<=$D$3,J12>0),$J$6,IF(AND(I11<=$D$3,I12>0),$I$6,IF(AND(H11<=$D$3,H12>0),$H$6,IF(AND(G11<=$D$3,G12>0),$G$6,IF(AND(F11<=$D$3,F12>0),$F$6,"0"))))) -> 0 | L12: =IF(C10<=$H$3,SUM($F12:$I12)*(1+'Summary and Assumptions'!$D$103),"") -> 0
B13: F | C13: =C10+1 -> 3 | D13: =IF(C13<=$H$3,"Company"&" "&C13,"") -> Company 3 | E13: FQ End Date | F13: =IFERROR(IF(F14>0,(DATE(YEAR(F14),((INT((MONTH(F14)-1)/3)+1)*3)+1,1)-1),"-"),"NA") -> 44377 | G13: =IFERROR(IF(G14>0,(DATE(YEAR(G14),((INT((MONTH(G14)-1)/3)+1)*3)+1,1)-1),"-"),"NA") -> 44834 | H13: =IFERROR(IF(H14>0,(DATE(YEAR(H14),((INT((MONTH(H14)-1)/3)+1)*3)+1,1)-1),"-"),"NA") -> 44834 | I13: =IFERROR(IF(I14>0,(DATE(YEAR(I14),((INT((MONTH(I14)-1)/3)+1)*3)+1,1)-1),"-"),"NA") -> 45382 | J13: =IFERROR(IF(J14>0,(DATE(YEAR(J14),((INT((MONTH(J14)-1)/3)+1)*3)+1,1)-1),"-"),"NA") -> 45838 | L13: =IFERROR(IF(L14>0,(DATE(YEAR(L14),((INT((MONTH(L14)-1)/3)+1)*3)+1,1)-1),"-"),"") -> 45838 | O13: =IF(F14<=TODAY(),C13,"0") -> 0 | P13: =IF(F14<=TODAY(),D13,"0") -> 0 | Q13: =IF(F14<=TODAY(),F14,"0") -> 0 | R13: =IF(F14<=TODAY(),F15,0) -> 0 | S13: =IF(G14<=TODAY(),G15,0) -> 0 | T13: =IF(H14<=TODAY(),H15,0) -> 0 | U13: =IF(I14<=TODAY(),I15,0) -> 0 | V13: =IF(J14<=TODAY(),J15,0) -> 0 | W13: =IF(L14<=TODAY(),L15,0) -> 0 | X13: =IF(K14<=TODAY(),K15,"-") -> 0 | Z13: =C13 -> 3 | AA13: =D13 -> Company 3 | AB13: =F14 -> 44302 | AC13: =IF(F14>TODAY(),F15,"0") -> 1250000 | AD13: =IF(G14>TODAY(),G15,"0") -> 112500 | AE13: =IF(H14>TODAY(),H15,"0") -> 937500 | AF13: =IF(I14>TODAY(),I15,"0") -> 750000 | AG13: =IF(J14>TODAY(),J15,"0") -> 0 | AH13: =IF(L14>TODAY(),L15,"0") -> 0
E14: Date | F14: =IF(C13<=$H$3,IF((F11+('Summary and Assumptions'!$K$118*7))>$D$3,(F11+('Summary and Assumptions'!$K$118*7)),($D$3+$H$4)),"") -> 44302 | G14: =IF($C13<=$H$3,IF((F14+('Summary and Assumptions'!$K$119*7))>$D$3,(F14+('Summary and Assumptions'!$K$119*7)),($D$3+$H$4)),"") -> 44757 | H14: =IF($C13<=$H$3,IF((F14+('Summary and Assumptions'!$K$120*7))>$D$3,(F14+('Summary and Assumptions'!$K$120*7)),($D$3+$H$4)),"") -> 44827 | I14: =IF($C13<=$H$3,IF((H14+('Summary and Assumptions'!$K$121*7))>$D$3,(H14+('Summary and Assumptions'!$K$121*7)),($D$3+$H$4)),"") -> 45359 | J14: =IF($C13<=$H$3,IF((I14+('Summary and Assumptions'!$K$122*7))>$D$3,(I14+('Summary and Assumptions'!$K$122*7)),($D$3+$H$4)),"") -> 45807 | L14: =IF($C13<=$H$3,IF((J14+('Summary and Assumptions'!$K$123*7))>$D$3,(J14+('Summary and Assumptions'!$K$123*7)),($D$3+$H$4)),"") -> 45807
E15: Amount | F15: =IF(C13<=$H$3,'Summary and Assumptions'!$D$101,"") -> 1250000 | G15: =IF(C13<=$H$3,F15*'Summary and Assumptions'!$K$111*'Summary and Assumptions'!$K$102,"") -> 112500 | H15: =IF(C13<=$H$3,$F15*'Summary and Assumptions'!$K$112*'Summary and Assumptions'!$K$103,"") -> 937500 | I15: =IF(C13<=$H$3,$F15*'Summary and Assumptions'!$K$113*'Summary and Assumptions'!$K$104,"") -> 750000 | J15: =IF(C13<=$H$3,$F15*'Summary and Assumptions'!$K$114*'Summary and Assumptions'!$K$105,"") -> 0 | K15: =IF(AND(J14<=$D$3,J15>0),$J$6,IF(AND(I14<=$D$3,I15>0),$I$6,IF(AND(H14<=$D$3,H15>0),$H$6,IF(AND(G14<=$D$3,G15>0),$G$6,IF(AND(F14<=$D$3,F15>0),$F$6,"0"))))) -> 0 | L15: =IF(C13<=$H$3,SUM($F15:$I15)*(1+'Summary and Assumptions'!$D$103),"") -> 0
B16: F | C16: =C13+1 -> 4 | D16: =IF(C16<=$H$3,"Company"&" "&C16,"") -> Company 4 | E16: FQ End Date | F16: =IFERROR(IF(F17>0,(DATE(YEAR(F17),((INT((MONTH(F17)-1)/3)+1)*3)+1,1)-1),"-"),"NA") -> 44377 | G16: =IFERROR(IF(G17>0,(DATE(YEAR(G17),((INT((MONTH(G17)-1)/3)+1)*3)+1,1)-1),"-"),"NA") -> 44834 | H16: =IFERROR(IF(H17>0,(DATE(YEAR(H17),((INT((MONTH(H17)-1)/3)+1)*3)+1,1)-1),"-"),"NA") -> 44926 | I16: =IFERROR(IF(I17>0,(DATE(YEAR(I17),((INT((MONTH(I17)-1)/3)+1)*3)+1,1)-1),"-"),"NA") -> 45473 | J16: =IFERROR(IF(J17>0,(DATE(YEAR(J17),((INT((MONTH(J17)-1)/3)+1)*3)+1,1)-1),"-"),"NA") -> 45930 | L16: =IFERROR(IF(L17>0,(DATE(YEAR(L17),((INT((MONTH(L17)-1)/3)+1)*3)+1,1)-1),"-"),"") -> 45930 | O16: =IF(F17<=TODAY(),C16,"0") -> 0 | P16: =IF(F17<=TODAY(),D16,"0") -> 0 | Q16: =IF(F17<=TODAY(),F17,"0") -> 0 | R16: =IF(F17<=TODAY(),F18,0) -> 0 | S16: =IF(G17<=TODAY(),G18,0) -> 0 | T16: =IF(H17<=TODAY(),H18,0) -> 0 | U16: =IF(I17<=TODAY(),I18,0) -> 0 | V16: =IF(J17<=TODAY(),J18,0) -> 0 | W16: =IF(L17<=TODAY(),L18,0) -> 0 | X16: =IF(K17<=TODAY(),K18,"-") -> 0 | Z16: =C16 -> 4 | AA16: =D16 -> Company 4 | AB16: =F17 -> 44337 | AC16: =IF(F17>TODAY(),F18,"0") -> 1250000 | AD16: =IF(G17>TODAY(),G18,"0") -> 112500 | AE16: =IF(H17>TODAY(),H18,"0") -> 937500 | AF16: =IF(I17>TODAY(),I18,"0") -> 750000 | AG16: =IF(J17>TODAY(),J18,"0") -> 0 | AH16: =IF(L17>TODAY(),L18,"0") -> 0
E17: Date | F17: =IF(C16<=$H$3,IF((F14+('Summary and Assumptions'!$K$118*7))>$D$3,(F14+('Summary and Assumptions'!$K$118*7)),($D$3+$H$4)),"") -> 44337 | G17: =IF($C16<=$H$3,IF((F17+('Summary and Assumptions'!$K$119*7))>$D$3,(F17+('Summary and Assumptions'!$K$119*7)),($D$3+$H$4)),"") -> 44792 | H17: =IF($C16<=$H$3,IF((F17+('Summary and Assumptions'!$K$120*7))>$D$3,(F17+('Summary and Assumptions'!$K$120*7)),($D$3+$H$4)),"") -> 44862 | I17: =IF($C16<=$H$3,IF((H17+('Summary and Assumptions'!$K$121*7))>$D$3,(H17+('Summary and Assumptions'!$K$121*7)),($D$3+$H$4)),"") -> 45394 | J17: =IF($C16<=$H$3,IF((I17+('Summary and Assumptions'!$K$122*7))>$D$3,(I17+('Summary and Assumptions'!$K$122*7)),($D$3+$H$4)),"") -> 45842 | L17: =IF($C16<=$H$3,IF((J17+('Summary and Assumptions'!$K$123*7))>$D$3,(J17+('Summary and Assumptions'!$K$123*7)),($D$3+$H$4)),"") -> 45842
E18: Amount | F18: =IF(C16<=$H$3,'Summary and Assumptions'!$D$101,"") -> 1250000 | G18: =IF(C16<=$H$3,F18*'Summary and Assumptions'!$K$111*'Summary and Assumptions'!$K$102,"") -> 112500 | H18: =IF(C16<=$H$3,$F18*'Summary and Assumptions'!$K$112*'Summary and Assumptions'!$K$103,"") -> 937500 | I18: =IF(C16<=$H$3,$F18*'Summary and Assumptions'!$K$113*'Summary and Assumptions'!$K$104,"") -> 750000 | J18: =IF(C16<=$H$3,$F18*'Summary and Assumptions'!$K$114*'Summary and Assumptions'!$K$105,"") -> 0 | K18: =IF(AND(J17<=$D$3,J18>0),$J$6,IF(AND(I17<=$D$3,I18>0),$I$6,IF(AND(H17<=$D$3,H18>0),$H$6,IF(AND(G17<=$D$3,G18>0),$G$6,IF(AND(F17<=$D$3,F18>0),$F$6,"0"))))) -> 0 | L18: =IF(C16<=$H$3,SUM($F18:$I18)*(1+'Summary and Assumptions'!$D$103),"") -> 0
B19: F | C19: =C16+1 -> 5 | D19: =IF(C19<=$H$3,"Company"&" "&C19,"") -> Company 5 | E19: FQ End Date | F19: =IFERROR(IF(F20>0,(DATE(YEAR(F20),((INT((MONTH(F20)-1)/3)+1)*3)+1,1)-1),"-"),"NA") -> 44377 | G19: =IFERROR(IF(G20>0,(DATE(YEAR(G20),((INT((MONTH(G20)-1)/3)+1)*3)+1,1)-1),"-"),"NA") -> 44834 | H19: =IFERROR(IF(H20>0,(DATE(YEAR(H20),((INT((MONTH(H20)-1)/3)+1)*3)+1,1)-1),"-"),"NA") -> 44926 | I19: =IFERROR(IF(I20>0,(DATE(YEAR(I20),((INT((MONTH(I20)-1)/3)+1)*3)+1,1)-1),"-"),"NA") -> 45473 | J19: =IFERROR(IF(J20>0,(DATE(YEAR(J20),((INT((MONTH(J20)-1)/3)+1)*3)+1,1)-1),"-"),"NA") -> 45930 | L19: =IFERROR(IF(L20>0,(DATE(YEAR(L20),((INT((MONTH(L20)-1)/3)+1)*3)+1,1)-1),"-"),"") -> 45930 | O19: =IF(F20<=TODAY(),C19,"0") -> 0 | P19: =IF(F20<=TODAY(),D19,"0") -> 0 | Q19: =IF(F20<=TODAY(),F20,"0") -> 0 | R19: =IF(F20<=TODAY(),F21,0) -> 0 | S19: =IF(G20<=TODAY(),G21,0) -> 0 | T19: =IF(H20<=TODAY(),H21,0) -> 0 | U19: =IF(I20<=TODAY(),I21,0) -> 0 | V19: =IF(J20<=TODAY(),J21,0) -> 0 | W19: =IF(L20<=TODAY(),L21,0) -> 0 | X19: =IF(K20<=TODAY(),K21,"-") -> 0 | Z19: =C19 -> 5 | AA19: =D19 -> Company 5 | AB19: =F20 -> 44372 | AC19: =IF(F20>TODAY(),F21,"0") -> 1250000 | AD19: =IF(G20>TODAY(),G21,"0") -> 112500 | AE19: =IF(H20>TODAY(),H21,"0") -> 937500 | AF19: =IF(I20>TODAY(),I21,"0") -> 750000 | AG19: =IF(J20>TODAY(),J21,"0") -> 0 | AH19: =IF(L20>TODAY(),L21,"0") -> 0
E20: Date | F20: =IF(C19<=$H$3,IF((F17+('Summary and Assumptions'!$K$118*7))>$D$3,(F17+('Summary and Assumptions'!$K$118*7)),($D$3+$H$4)),"") -> 44372 | G20: =IF($C19<=$H$3,IF((F20+('Summary and Assumptions'!$K$119*7))>$D$3,(F20+('Summary and Assumptions'!$K$119*7)),($D$3+$H$4)),"") -> 44827 | H20: =IF($C19<=$H$3,IF((F20+('Summary and Assumptions'!$K$120*7))>$D$3,(F20+('Summary and Assumptions'!$K$120*7)),($D$3+$H$4)),"") -> 44897 | I20: =IF($C19<=$H$3,IF((H20+('Summary and Assumptions'!$K$121*7))>$D$3,(H20+('Summary and Assumptions'!$K$121*7)),($D$3+$H$4)),"") -> 45429 | J20: =IF($C19<=$H$3,IF((I20+('Summary and Assumptions'!$K$122*7))>$D$3,(I20+('Summary and Assumptions'!$K$122*7)),($D$3+$H$4)),"") -> 45877 | L20: =IF($C19<=$H$3,IF((J20+('Summary and Assumptions'!$K$123*7))>$D$3,(J20+('Summary and Assumptions'!$K$123*7)),($D$3+$H$4)),"") -> 45877
E21: Amount | F21: =IF(C19<=$H$3,'Summary and Assumptions'!$D$101,"") -> 1250000 | G21: =IF(C19<=$H$3,F21*'Summary and Assumptions'!$K$111*'Summary and Assumptions'!$K$102,"") -> 112500 | H21: =IF(C19<=$H$3,$F21*'Summary and Assumptions'!$K$112*'Summary and Assumptions'!$K$103,"") -> 937500 | I21: =IF(C19<=$H$3,$F21*'Summary and Assumptions'!$K$113*'Summary and Assumptions'!$K$104,"") -> 750000 | J21: =IF(C19<=$H$3,$F21*'Summary and Assumptions'!$K$114*'Summary and Assumptions'!$K$105,"") -> 0 | K21: =IF(AND(J20<=$D$3,J21>0),$J$6,IF(AND(I20<=$D$3,I21>0),$I$6,IF(AND(H20<=$D$3,H21>0),$H$6,IF(AND(G20<=$D$3,G21>0),$G$6,IF(AND(F20<=$D$3,F21>0),$F$6,"0"))))) -> 0 | L21: =IF(C19<=$H$3,SUM($F21:$I21)*(1+'Summary and Assumptions'!$D$103),"") -> 0
B22: F | C22: =C19+1 -> 6 | D22: =IF(C22<=$H$3,"Company"&" "&C22,"") -> Company 6 | E22: FQ End Date | F22: =IFERROR(IF(F23>0,(DATE(YEAR(F23),((INT((MONTH(F23)-1)/3)+1)*3)+1,1)-1),"-"),"NA") -> 44469 | G22: =IFERROR(IF(G23>0,(DATE(YEAR(G23),((INT((MONTH(G23)-1)/3)+1)*3)+1,1)-1),"-"),"NA") -> 44926 | H22: =IFERROR(IF(H23>0,(DATE(YEAR(H23),((INT((MONTH(H23)-1)/3)+1)*3)+1,1)-1),"-"),"NA") -> 45016 | I22: =IFERROR(IF(I23>0,(DATE(YEAR(I23),((INT((MONTH(I23)-1)/3)+1)*3)+1,1)-1),"-"),"NA") -> 45473 | J22: =IFERROR(IF(J23>0,(DATE(YEAR(J23),((INT((MONTH(J23)-1)/3)+1)*3)+1,1)-1),"-"),"NA") -> 45930 | L22: =IFERROR(IF(L23>0,(DATE(YEAR(L23),((INT((MONTH(L23)-1)/3)+1)*3)+1,1)-1),"-"),"") -> 45930 | O22: =IF(F23<=TODAY(),C22,"0") -> 0 | P22: =IF(F23<=TODAY(),D22,"0") -> 0 | Q22: =IF(F23<=TODAY(),F23,"0") -> 0 | R22: =IF(F23<=TODAY(),F24,0) -> 0 | S22: =IF(G23<=TODAY(),G24,0) -> 0 | T22: =IF(H23<=TODAY(),H24,0) -> 0 | U22: =IF(I23<=TODAY(),I24,0) -> 0 | V22: =IF(J23<=TODAY(),J24,0) -> 0 | W22: =IF(L23<=TODAY(),L24,0) -> 0 | X22: =IF(K23<=TODAY(),K24,"-") -> 0 | Z22: =C22 -> 6 | AA22: =D22 -> Company 6 | AB22: =F23 -> 44407 | AC22: =IF(F23>TODAY(),F24,"0") -> 1250000 | AD22: =IF(G23>TODAY(),G24,"0") -> 112500 | AE22: =IF(H23>TODAY(),H24,"0") -> 937500 | AF22: =IF(I23>TODAY(),I24,"0") -> 750000 | AG22: =IF(J23>TODAY(),J24,"0") -> 0 | AH22: =IF(L23>TODAY(),L24,"0") -> 0
E23: Date | F23: =IF(C22<=$H$3,IF((F20+('Summary and Assumptions'!$K$118*7))>$D$3,(F20+('Summary and Assumptions'!$K$118*7)),($D$3+$H$4)),"") -> 44407 | G23: =IF($C22<=$H$3,IF((F23+('Summary and Assumptions'!$K$119*7))>$D$3,(F23+('Summary and Assumptions'!$K$119*7)),($D$3+$H$4)),"") -> 44862 | H23: =IF($C22<=$H$3,IF((F23+('Summary and Assumptions'!$K$120*7))>$D$3,(F23+('Summary and Assumptions'!$K$120*7)),($D$3+$H$4)),"") -> 44932 | I23: =IF($C22<=$H$3,IF((H23+('Summary and Assumptions'!$K$121*7))>$D$3,(H23+('Summary and Assumptions'!$K$121*7)),($D$3+$H$4)),"") -> 45464 | J23: =IF($C22<=$H$3,IF((I23+('Summary and Assumptions'!$K$122*7))>$D$3,(I23+('Summary and Assumptions'!$K$122*7)),($D$3+$H$4)),"") -> 45912 | L23: =IF($C22<=$H$3,IF((J23+('Summary and Assumptions'!$K$123*7))>$D$3,(J23+('Summary and Assumptions'!$K$123*7)),($D$3+$H$4)),"") -> 45912
E24: Amount | F24: =IF(C22<=$H$3,'Summary and Assumptions'!$D$101,"") -> 1250000 | G24: =IF(C22<=$H$3,F24*'Summary and Assumptions'!$K$111*'Summary and Assumptions'!$K$102,"") -> 112500 | H24: =IF(C22<=$H$3,$F24*'Summary and Assumptions'!$K$112*'Summary and Assumptions'!$K$103,"") -> 937500 | I24: =IF(C22<=$H$3,$F24*'Summary and Assumptions'!$K$113*'Summary and Assumptions'!$K$104,"") -> 750000 | J24: =IF(C22<=$H$3,$F24*'Summary and Assumptions'!$K$114*'Summary and Assumptions'!$K$105,"") -> 0 | K24: =IF(AND(J23<=$D$3,J24>0),$J$6,IF(AND(I23<=$D$3,I24>0),$I$6,IF(AND(H23<=$D$3,H24>0),$H$6,IF(AND(G23<=$D$3,G24>0),$G$6,IF(AND(F23<=$D$3,F24>0),$F$6,"0"))))) -> 0 | L24: =IF(C22<=$H$3,SUM($F24:$I24)*(1+'Summary and Assumptions'!$D$103),"") -> 0
B25: F | C25: =C22+1 -> 7 | D25: =IF(C25<=$H$3,"Company"&" "&C25,"") -> Company 7 | E25: FQ End Date | F25: =IFERROR(IF(F26>0,(DATE(YEAR(F26),((INT((MONTH(F26)-1)/3)+1)*3)+1,1)-1),"-"),"NA") -> 44469 | G25: =IFERROR(IF(G26>0,(DATE(YEAR(G26),((INT((MONTH(G26)-1)/3)+1)*3)+1,1)-1),"-"),"NA") -> 44926 | H25: =IFERROR(IF(H26>0,(DATE(YEAR(H26),((INT((MONTH(H26)-1)/3)+1)*3)+1,1)-1),"-"),"NA") -> 45016 | I25: =IFERROR(IF(I26>0,(DATE(YEAR(I26),((INT((MONTH(I26)-1)/3)+1)*3)+1,1)-1),"-"),"NA") -> 45565 | J25: =IFERROR(IF(J26>0,(DATE(YEAR(J26),((INT((MONTH(J26)-1)/3)+1)*3)+1,1)-1),"-"),"NA") -> 46022 | L25: =IFERROR(IF(L26>0,(DATE(YEAR(L26),((INT((MONTH(L26)-1)/3)+1)*3)+1,1)-1),"-"),"") -> 46022 | O25: =IF(F26<=TODAY(),C25,"0") -> 0 | P25: =IF(F26<=TODAY(),D25,"0") -> 0 | Q25: =IF(F26<=TODAY(),F26,"0") -> 0 | R25: =IF(F26<=TODAY(),F27,0) -> 0 | S25: =IF(G26<=TODAY(),G27,0) -> 0 | T25: =IF(H26<=TODAY(),H27,0) -> 0 | U25: =IF(I26<=TODAY(),I27,0) -> 0 | V25: =IF(J26<=TODAY(),J27,0) -> 0 | W25: =IF(L26<=TODAY(),L27,0) -> 0 | X25: =IF(K26<=TODAY(),K27,"-") -> 0 | Z25: =C25 -> 7 | AA25: =D25 -> Company 7 | AB25: =F26 -> 44442 | AC25: =IF(F26>TODAY(),F27,"0") -> 1250000 | AD25: =IF(G26>TODAY(),G27,"0") -> 112500 | AE25: =IF(H26>TODAY(),H27,"0") -> 937500 | AF25: =IF(I26>TODAY(),I27,"0") -> 750000 | AG25: =IF(J26>TODAY(),J27,"0") -> 0 | AH25: =IF(L26>TODAY(),L27,"0") -> 0
E26: Date | F26: =IF(C25<=$H$3,IF((F23+('Summary and Assumptions'!$K$118*7))>$D$3,(F23+('Summary and Assumptions'!$K$118*7)),($D$3+$H$4)),"") -> 44442 | G26: =IF($C25<=$H$3,IF((F26+('Summary and Assumptions'!$K$119*7))>$D$3,(F26+('Summary and Assumptions'!$K$119*7)),($D$3+$H$4)),"") -> 44897 | H26: =IF($C25<=$H$3,IF((F26+('Summary and Assumptions'!$K$120*7))>$D$3,(F26+('Summary and Assumptions'!$K$120*7)),($D$3+$H$4)),"") -> 44967 | I26: =IF($C25<=$H$3,IF((H26+('Summary and Assumptions'!$K$121*7))>$D$3,(H26+('Summary and Assumptions'!$K$121*7)),($D$3+$H$4)),"") -> 45499 | J26: =IF($C25<=$H$3,IF((I26+('Summary and Assumptions'!$K$122*7))>$D$3,(I26+('Summary and Assumptions'!$K$122*7)),($D$3+$H$4)),"") -> 45947 | L26: =IF($C25<=$H$3,IF((J26+('Summary and Assumptions'!$K$123*7))>$D$3,(J26+('Summary and Assumptions'!$K$123*7)),($D$3+$H$4)),"") -> 45947
E27: Amount | F27: =IF(C25<=$H$3,'Summary and Assumptions'!$D$101,"") -> 1250000 | G27: =IF(C25<=$H$3,F27*'Summary and Assumptions'!$K$111*'Summary and Assumptions'!$K$102,"") -> 112500 | H27: =IF(C25<=$H$3,$F27*'Summary and Assumptions'!$K$112*'Summary and Assumptions'!$K$103,"") -> 937500 | I27: =IF(C25<=$H$3,$F27*'Summary and Assumptions'!$K$113*'Summary and Assumptions'!$K$104,"") -> 750000 | J27: =IF(C25<=$H$3,$F27*'Summary and Assumptions'!$K$114*'Summary and Assumptions'!$K$105,"") -> 0 | K27: =IF(AND(J26<=$D$3,J27>0),$J$6,IF(AND(I26<=$D$3,I27>0),$I$6,IF(AND(H26<=$D$3,H27>0),$H$6,IF(AND(G26<=$D$3,G27>0),$G$6,IF(AND(F26<=$D$3,F27>0),$F$6,"0"))))) -> 0 | L27: =IF(C25<=$H$3,SUM($F27:$I27)*(1+'Summary and Assumptions'!$D$103),"") -> 0
B28: F | C28: =C25+1 -> 8 | D28: =IF(C28<=$H$3,"Company"&" "&C28,"") -> Company 8 | E28: FQ End Date | F28: =IFERROR(IF(F29>0,(DATE(YEAR(F29),((INT((MONTH(F29)-1)/3)+1)*3)+1,1)-1),"-"),"NA") -> 44561 | G28: =IFERROR(IF(G29>0,(DATE(YEAR(G29),((INT((MONTH(G29)-1)/3)+1)*3)+1,1)-1),"-"),"NA") -> 45016 | H28: =IFERROR(IF(H29>0,(DATE(YEAR(H29),((INT((MONTH(H29)-1)/3)+1)*3)+1,1)-1),"-"),"NA") -> 45016 | I28: =IFERROR(IF(I29>0,(DATE(YEAR(I29),((INT((MONTH(I29)-1)/3)+1)*3)+1,1)-1),"-"),"NA") -> 45565 | J28: =IFERROR(IF(J29>0,(DATE(YEAR(J29),((INT((MONTH(J29)-1)/3)+1)*3)+1,1)-1),"-"),"NA") -> 46022 | L28: =IFERROR(IF(L29>0,(DATE(YEAR(L29),((INT((MONTH(L29)-1)/3)+1)*3)+1,1)-1),"-"),"") -> 46022 | O28: =IF(F29<=TODAY(),C28,"0") -> 0 | P28: =IF(F29<=TODAY(),D28,"0") -> 0 | Q28: =IF(F29<=TODAY(),F29,"0") -> 0 | R28: =IF(F29<=TODAY(),F30,0) -> 0 | S28: =IF(G29<=TODAY(),G30,0) -> 0 | T28: =IF(H29<=TODAY(),H30,0) -> 0 | U28: =IF(I29<=TODAY(),I30,0) -> 0 | V28: =IF(J29<=TODAY(),J30,0) -> 0 | W28: =IF(L29<=TODAY(),L30,0) -> 0 | X28: =IF(K29<=TODAY(),K30,"-") -> 0 | Z28: =C28 -> 8 | AA28: =D28 -> Company 8 | AB28: =F29 -> 44477 | AC28: =IF(F29>TODAY(),F30,"0") -> 1250000 | AD28: =IF(G29>TODAY(),G30,"0") -> 112500 | AE28: =IF(H29>TODAY(),H30,"0") -> 937500 | AF28: =IF(I29>TODAY(),I30,"0") -> 750000 | AG28: =IF(J29>TODAY(),J30,"0") -> 0 | AH28: =IF(L29>TODAY(),L30,"0") -> 0
E29: Date | F29: =IF(C28<=$H$3,IF((F26+('Summary and Assumptions'!$K$118*7))>$D$3,(F26+('Summary and Assumptions'!$K$118*7)),($D$3+$H$4)),"") -> 44477 | G29: =IF($C28<=$H$3,IF((F29+('Summary and Assumptions'!$K$119*7))>$D$3,(F29+('Summary and Assumptions'!$K$119*7)),($D$3+$H$4)),"") -> 44932 | H29: =IF($C28<=$H$3,IF((F29+('Summary and Assumptions'!$K$120*7))>$D$3,(F29+('Summary and Assumptions'!$K$120*7)),($D$3+$H$4)),"") -> 45002 | I29: =IF($C28<=$H$3,IF((H29+('Summary and Assumptions'!$K$121*7))>$D$3,(H29+('Summary and Assumptions'!$K$121*7)),($D$3+$H$4)),"") -> 45534 | J29: =IF($C28<=$H$3,IF((I29+('Summary and Assumptions'!$K$122*7))>$D$3,(I29+('Summary and Assumptions'!$K$122*7)),($D$3+$H$4)),"") -> 45982 | L29: =IF($C28<=$H$3,IF((J29+('Summary and Assumptions'!$K$123*7))>$D$3,(J29+('Summary and Assumptions'!$K$123*7)),($D$3+$H$4)),"") -> 45982
E30: Amount | F30: =IF(C28<=$H$3,'Summary and Assumptions'!$D$101,"") -> 1250000 | G30: =IF(C28<=$H$3,F30*'Summary and Assumptions'!$K$111*'Summary and Assumptions'!$K$102,"") -> 112500 | H30: =IF(C28<=$H$3,$F30*'Summary and Assumptions'!$K$112*'Summary and Assumptions'!$K$103,"") -> 937500 | I30: =IF(C28<=$H$3,$F30*'Summary and Assumptions'!$K$113*'Summary and Assumptions'!$K$104,"") -> 750000 | J30: =IF(C28<=$H$3,$F30*'Summary and Assumptions'!$K$114*'Summary and Assumptions'!$K$105,"") -> 0 | K30: =IF(AND(J29<=$D$3,J30>0),$J$6,IF(AND(I29<=$D$3,I30>0),$I$6,IF(AND(H29<=$D$3,H30>0),$H$6,IF(AND(G29<=$D$3,G30>0),$G$6,IF(AND(F29<=$D$3,F30>0),$F$6,"0"))))) -> 0 | L30: =IF(C28<=$H$3,SUM($F30:$I30)*(1+'Summary and Assumptions'!$D$103),"") -> 0
B31: F | C31: =C28+1 -> 9 | D31: =IF(C31<=$H$3,"Company"&" "&C31,"") -> Company 9 | E31: FQ End Date | F31: =IFERROR(IF(F32>0,(DATE(YEAR(F32),((INT((MONTH(F32)-1)/3)+1)*3)+1,1)-1),"-"),"NA") -> 44561 | G31: =IFERROR(IF(G32>0,(DATE(YEAR(G32),((INT((MONTH(G32)-1)/3)+1)*3)+1,1)-1),"-"),"NA") -> 45016 | H31: =IFERROR(IF(H32>0,(DATE(YEAR(H32),((INT((MONTH(H32)-1)/3)+1)*3)+1,1)-1),"-"),"NA") -> 45107 | I31: =IFERROR(IF(I32>0,(DATE(YEAR(I32),((INT((MONTH(I32)-1)/3)+1)*3)+1,1)-1),"-"),"NA") -> 45657 | J31: =IFERROR(IF(J32>0,(DATE(YEAR(J32),((INT((MONTH(J32)-1)/3)+1)*3)+1,1)-1),"-"),"NA") -> 46022 | L31: =IFERROR(IF(L32>0,(DATE(YEAR(L32),((INT((MONTH(L32)-1)/3)+1)*3)+1,1)-1),"-"),"") -> 46022 | O31: =IF(F32<=TODAY(),C31,"0") -> 0 | P31: =IF(F32<=TODAY(),D31,"0") -> 0 | Q31: =IF(F32<=TODAY(),F32,"0") -> 0 | R31: =IF(F32<=TODAY(),F33,0) -> 0 | S31: =IF(G32<=TODAY(),G33,0) -> 0 | T31: =IF(H32<=TODAY(),H33,0) -> 0 | U31: =IF(I32<=TODAY(),I33,0) -> 0 | V31: =IF(J32<=TODAY(),J33,0) -> 0 | W31: =IF(L32<=TODAY(),L33,0) -> 0 | X31: =IF(K32<=TODAY(),K33,"-") -> 0 | Z31: =C31 -> 9 | AA31: =D31 -> Company 9 | AB31: =F32 -> 44512 | AC31: =IF(F32>TODAY(),F33,"0") -> 1250000 | AD31: =IF(G32>TODAY(),G33,"0") -> 112500 | AE31: =IF(H32>TODAY(),H33,"0") -> 937500 | AF31: =IF(I32>TODAY(),I33,"0") -> 750000 | AG31: =IF(J32>TODAY(),J33,"0") -> 0 | AH31: =IF(L32>TODAY(),L33,"0") -> 0
E32: Date | F32: =IF(C31<=$H$3,IF((F29+('Summary and Assumptions'!$K$118*7))>$D$3,(F29+('Summary and Assumptions'!$K$118*7)),($D$3+$H$4)),"") -> 44512 | G32: =IF($C31<=$H$3,IF((F32+('Summary and Assumptions'!$K$119*7))>$D$3,(F32+('Summary and Assumptions'!$K$119*7)),($D$3+$H$4)),"") -> 44967 | H32: =IF($C31<=$H$3,IF((F32+('Summary and Assumptions'!$K$120*7))>$D$3,(F32+('Summary and Assumptions'!$K$120*7)),($D$3+$H$4)),"") -> 45037 | I32: =IF($C31<=$H$3,IF((H32+('Summary and Assumptions'!$K$121*7))>$D$3,(H32+('Summary and Assumptions'!$K$121*7)),($D$3+$H$4)),"") -> 45569 | J32: =IF($C31<=$H$3,IF((I32+('Summary and Assumptions'!$K$122*7))>$D$3,(I32+('Summary and Assumptions'!$K$122*7)),($D$3+$H$4)),"") -> 46017 | L32: =IF($C31<=$H$3,IF((J32+('Summary and Assumptions'!$K$123*7))>$D$3,(J32+('Summary and Assumptions'!$K$123*7)),($D$3+$H$4)),"") -> 46017
E33: Amount | F33: =IF(C31<=$H$3,'Summary and Assumptions'!$D$101,"") -> 1250000 | G33: =IF(C31<=$H$3,F33*'Summary and Assumptions'!$K$111*'Summary and Assumptions'!$K$102,"") -> 112500 | H33: =IF(C31<=$H$3,$F33*'Summary and Assumptions'!$K$112*'Summary and Assumptions'!$K$103,"") -> 937500 | I33: =IF(C31<=$H$3,$F33*'Summary and Assumptions'!$K$113*'Summary and Assumptions'!$K$104,"") -> 750000 | J33: =IF(C31<=$H$3,$F33*'Summary and Assumptions'!$K$114*'Summary and Assumptions'!$K$105,"") -> 0 | K33: =IF(AND(J32<=$D$3,J33>0),$J$6,IF(AND(I32<=$D$3,I33>0),$I$6,IF(AND(H32<=$D$3,H33>0),$H$6,IF(AND(G32<=$D$3,G33>0),$G$6,IF(AND(F32<=$D$3,F33>0),$F$6,"0"))))) -> 0 | L33: =IF(C31<=$H$3,SUM($F33:$I33)*(1+'Summary and Assumptions'!$D$103),"") -> 0
B34: F | C34: =C31+1 -> 10 | D34: =IF(C34<=$H$3,"Company"&" "&C34,"") -> Company 10 | E34: FQ End Date | F34: =IFERROR(IF(F35>0,(DATE(YEAR(F35),((INT((MONTH(F35)-1)/3)+1)*3)+1,1)-1),"-"),"NA") -> 44561 | G34: =IFERROR(IF(G35>0,(DATE(YEAR(G35),((INT((MONTH(G35)-1)/3)+1)*3)+1,1)-1),"-"),"NA") -> 45016 | H34: =IFERROR(IF(H35>0,(DATE(YEAR(H35),((INT((MONTH(H35)-1)/3)+1)*3)+1,1)-1),"-"),"NA") -> 45107 | I34: =IFERROR(IF(I35>0,(DATE(YEAR(I35),((INT((MONTH(I35)-1)/3)+1)*3)+1,1)-1),"-"),"NA") -> 45657 | J34: =IFERROR(IF(J35>0,(DATE(YEAR(J35),((INT((MONTH(J35)-1)/3)+1)*3)+1,1)-1),"-"),"NA") -> 46112 | L34: =IFERROR(IF(L35>0,(DATE(YEAR(L35),((INT((MONTH(L35)-1)/3)+1)*3)+1,1)-1),"-"),"") -> 46112 | O34: =IF(F35<=TODAY(),C34,"0") -> 0 | P34: =IF(F35<=TODAY(),D34,"0") -> 0 | Q34: =IF(F35<=TODAY(),F35,"0") -> 0 | R34: =IF(F35<=TODAY(),F36,0) -> 0 | S34: =IF(G35<=TODAY(),G36,0) -> 0 | T34: =IF(H35<=TODAY(),H36,0) -> 0 | U34: =IF(I35<=TODAY(),I36,0) -> 0 | V34: =IF(J35<=TODAY(),J36,0) -> 0 | W34: =IF(L35<=TODAY(),L36,0) -> 0 | X34: =IF(K35<=TODAY(),K36,"-") -> 0 | Z34: =C34 -> 10 | AA34: =D34 -> Company 10 | AB34: =F35 -> 44547 | AC34: =IF(F35>TODAY(),F36,"0") -> 1250000 | AD34: =IF(G35>TODAY(),G36,"0") -> 112500 | AE34: =IF(H35>TODAY(),H36,"0") -> 937500 | AF34: =IF(I35>TODAY(),I36,"0") -> 750000 | AG34: =IF(J35>TODAY(),J36,"0") -> 0 | AH34: =IF(L35>TODAY(),L36,"0") -> 0
E35: Date | F35: =IF(C34<=$H$3,IF((F32+('Summary and Assumptions'!$K$118*7))>$D$3,(F32+('Summary and Assumptions'!$K$118*7)),($D$3+$H$4)),"") -> 44547 | G35: =IF($C34<=$H$3,IF((F35+('Summary and Assumptions'!$K$119*7))>$D$3,(F35+('Summary and Assumptions'!$K$119*7)),($D$3+$H$4)),"") -> 45002 | H35: =IF($C34<=$H$3,IF((F35+('Summary and Assumptions'!$K$120*7))>$D$3,(F35+('Summary and Assumptions'!$K$120*7)),($D$3+$H$4)),"") -> 45072 | I35: =IF($C34<=$H$3,IF((H35+('Summary and Assumptions'!$K$121*7))>$D$3,(H35+('Summary and Assumptions'!$K$121*7)),($D$3+$H$4)),"") -> 45604 | J35: =IF($C34<=$H$3,IF((I35+('Summary and Assumptions'!$K$122*7))>$D$3,(I35+('Summary and Assumptions'!$K$122*7)),($D$3+$H$4)),"") -> 46052 | L35: =IF($C34<=$H$3,IF((J35+('Summary and Assumptions'!$K$123*7))>$D$3,(J35+('Summary and Assumptions'!$K$123*7)),($D$3+$H$4)),"") -> 46052
E36: Amount | F36: =IF(C34<=$H$3,'Summary and Assumptions'!$D$101,"") -> 1250000 | G36: =IF(C34<=$H$3,F36*'Summary and Assumptions'!$K$111*'Summary and Assumptions'!$K$102,"") -> 112500 | H36: =IF(C34<=$H$3,$F36*'Summary and Assumptions'!$K$112*'Summary and Assumptions'!$K$103,"") -> 937500 | I36: =IF(C34<=$H$3,$F36*'Summary and Assumptions'!$K$113*'Summary and Assumptions'!$K$104,"") -> 750000 | J36: =IF(C34<=$H$3,$F36*'Summary and Assumptions'!$K$114*'Summary and Assumptions'!$K$105,"") -> 0 | K36: =IF(AND(J35<=$D$3,J36>0),$J$6,IF(AND(I35<=$D$3,I36>0),$I$6,IF(AND(H35<=$D$3,H36>0),$H$6,IF(AND(G35<=$D$3,G36>0),$G$6,IF(AND(F35<=$D$3,F36>0),$F$6,"0"))))) -> 0 | L36: =IF(C34<=$H$3,SUM($F36:$I36)*(1+'Summary and Assumptions'!$D$103),"") -> 0
B37: F | C37: =C34+1 -> 11 | D37: =IF(C37<=$H$3,"Company"&" "&C37,"") -> Company 11 | E37: FQ End Date | F37: =IFERROR(IF(F38>0,(DATE(YEAR(F38),((INT((MONTH(F38)-1)/3)+1)*3)+1,1)-1),"-"),"NA") -> 44651 | G37: =IFERROR(IF(G38>0,(DATE(YEAR(G38),((INT((MONTH(G38)-1)/3)+1)*3)+1,1)-1),"-"),"NA") -> 45107 | H37: =IFERROR(IF(H38>0,(DATE(YEAR(H38),((INT((MONTH(H38)-1)/3)+1)*3)+1,1)-1),"-"),"NA") -> 45107 | I37: =IFERROR(IF(I38>0,(DATE(YEAR(I38),((INT((MONTH(I38)-1)/3)+1)*3)+1,1)-1),"-"),"NA") -> 45657 | J37: =IFERROR(IF(J38>0,(DATE(YEAR(J38),((INT((MONTH(J38)-1)/3)+1)*3)+1,1)-1),"-"),"NA") -> 46112 | L37: =IFERROR(IF(L38>0,(DATE(YEAR(L38),((INT((MONTH(L38)-1)/3)+1)*3)+1,1)-1),"-"),"") -> 46112 | O37: =IF(F38<=TODAY(),C37,"0") -> 0 | P37: =IF(F38<=TODAY(),D37,"0") -> 0 | Q37: =IF(F38<=TODAY(),F38,"0") -> 0 | R37: =IF(F38<=TODAY(),F39,0) -> 0 | S37: =IF(G38<=TODAY(),G39,0) -> 0 | T37: =IF(H38<=TODAY(),H39,0) -> 0 | U37: =IF(I38<=TODAY(),I39,0) -> 0 | V37: =IF(J38<=TODAY(),J39,0) -> 0 | W37: =IF(L38<=TODAY(),L39,0) -> 0 | X37: =IF(K38<=TODAY(),K39,"-") -> 0 | Z37: =C37 -> 11 | AA37: =D37 -> Company 11 | AB37: =F38 -> 44582 | AC37: =IF(F38>TODAY(),F39,"0") -> 1250000 | AD37: =IF(G38>TODAY(),G39,"0") -> 112500 | AE37: =IF(H38>TODAY(),H39,"0") -> 937500 | AF37: =IF(I38>TODAY(),I39,"0") -> 750000 | AG37: =IF(J38>TODAY(),J39,"0") -> 0 | AH37: =IF(L38>TODAY(),L39,"0") -> 0
E38: Date | F38: =IF(C37<=$H$3,IF((F35+('Summary and Assumptions'!$K$118*7))>$D$3,(F35+('Summary and Assumptions'!$K$118*7)),($D$3+$H$4)),"") -> 44582 | G38: =IF($C37<=$H$3,IF((F38+('Summary and Assumptions'!$K$119*7))>$D$3,(F38+('Summary and Assumptions'!$K$119*7)),($D$3+$H$4)),"") -> 45037 | H38: =IF($C37<=$H$3,IF((F38+('Summary and Assumptions'!$K$120*7))>$D$3,(F38+('Summary and Assumptions'!$K$120*7)),($D$3+$H$4)),"") -> 45107 | I38: =IF($C37<=$H$3,IF((H38+('Summary and Assumptions'!$K$121*7))>$D$3,(H38+('Summary and Assumptions'!$K$121*7)),($D$3+$H$4)),"") -> 45639 | J38: =IF($C37<=$H$3,IF((I38+('Summary and Assumptions'!$K$122*7))>$D$3,(I38+('Summary and Assumptions'!$K$122*7)),($D$3+$H$4)),"") -> 46087 | L38: =IF($C37<=$H$3,IF((J38+('Summary and Assumptions'!$K$123*7))>$D$3,(J38+('Summary and Assumptions'!$K$123*7)),($D$3+$H$4)),"") -> 46087
E39: Amount | F39: =IF(C37<=$H$3,'Summary and Assumptions'!$D$101,"") -> 1250000 | G39: =IF(C37<=$H$3,F39*'Summary and Assumptions'!$K$111*'Summary and Assumptions'!$K$102,"") -> 112500 | H39: =IF(C37<=$H$3,$F39*'Summary and Assumptions'!$K$112*'Summary and Assumptions'!$K$103,"") -> 937500 | I39: =IF(C37<=$H$3,$F39*'Summary and Assumptions'!$K$113*'Summary and Assumptions'!$K$104,"") -> 750000 | J39: =IF(C37<=$H$3,$F39*'Summary and Assumptions'!$K$114*'Summary and Assumptions'!$K$105,"") -> 0 | K39: =IF(AND(J38<=$D$3,J39>0),$J$6,IF(AND(I38<=$D$3,I39>0),$I$6,IF(AND(H38<=$D$3,H39>0),$H$6,IF(AND(G38<=$D$3,G39>0),$G$6,IF(AND(F38<=$D$3,F39>0),$F$6,"0"))))) -> 0 | L39: =IF(C37<=$H$3,SUM($F39:$I39)*(1+'Summary and Assumptions'!$D$103),"") -> 0
B40: F | C40: =C37+1 -> 12 | D40: =IF(C40<=$H$3,"Company"&" "&C40,"") -> Company 12 | E40: FQ End Date | F40: =IFERROR(IF(F41>0,(DATE(YEAR(F41),((INT((MONTH(F41)-1)/3)+1)*3)+1,1)-1),"-"),"NA") -> 44651 | G40: =IFERROR(IF(G41>0,(DATE(YEAR(G41),((INT((MONTH(G41)-1)/3)+1)*3)+1,1)-1),"-"),"NA") -> 45107 | H40: =IFERROR(IF(H41>0,(DATE(YEAR(H41),((INT((MONTH(H41)-1)/3)+1)*3)+1,1)-1),"-"),"NA") -> 45199 | I40: =IFERROR(IF(I41>0,(DATE(YEAR(I41),((INT((MONTH(I41)-1)/3)+1)*3)+1,1)-1),"-"),"NA") -> 45747 | J40: =IFERROR(IF(J41>0,(DATE(YEAR(J41),((INT((MONTH(J41)-1)/3)+1)*3)+1,1)-1),"-"),"NA") -> 46203 | L40: =IFERROR(IF(L41>0,(DATE(YEAR(L41),((INT((MONTH(L41)-1)/3)+1)*3)+1,1)-1),"-"),"") -> 46203 | O40: =IF(F41<=TODAY(),C40,"0") -> 0 | P40: =IF(F41<=TODAY(),D40,"0") -> 0 | Q40: =IF(F41<=TODAY(),F41,"0") -> 0 | R40: =IF(F41<=TODAY(),F42,0) -> 0 | S40: =IF(G41<=TODAY(),G42,0) -> 0 | T40: =IF(H41<=TODAY(),H42,0) -> 0 | U40: =IF(I41<=TODAY(),I42,0) -> 0 | V40: =IF(J41<=TODAY(),J42,0) -> 0 | W40: =IF(L41<=TODAY(),L42,0) -> 0 | X40: =IF(K41<=TODAY(),K42,"-") -> 0 | Z40: =C40 -> 12 | AA40: =D40 -> Company 12 | AB40: =F41 -> 44617 | AC40: =IF(F41>TODAY(),F42,"0") -> 1250000 | AD40: =IF(G41>TODAY(),G42,"0") -> 112500 | AE40: =IF(H41>TODAY(),H42,"0") -> 937500 | AF40: =IF(I41>TODAY(),I42,"0") -> 750000 | AG40: =IF(J41>TODAY(),J42,"0") -> 0 | AH40: =IF(L41>TODAY(),L42,"0") -> 0
...

Sheet Model
B1: ='Summary and Assumptions'!D9 -> Fund Name
B2: Model
B3: Start | C3: =DATE(YEAR('Summary and Assumptions'!D10),1,1) -> 44197 | G3: ="FY "&YEAR(G4) -> FY 2021 | K3: ="FY "&YEAR(K4) -> FY 2022 | O3: ="FY "&YEAR(O4)&"E" -> FY 2023E | S3: ="FY "&YEAR(S4)&"E" -> FY 2024E | W3: ="FY "&YEAR(W4)&"E" -> FY 2025E | AA3: ="FY "&YEAR(AA4)&"E" -> FY 2026E | AE3: ="FY "&YEAR(AE4)&"E" -> FY 2027E | AI3: ="FY "&YEAR(AI4)&"E" -> FY 2028E | AM3: ="FY "&YEAR(AM4)&"E" -> FY 2029E | AQ3: ="FY "&YEAR(AQ4)&"E" -> FY 2030E | AU3: ="FY "&YEAR(AU4)&"E" -> FY 2031E
B4: Today | C4: ='Summary and Assumptions'!D13 -> 43958 | D4: =DATE(YEAR(C3),((INT((MONTH(C3)-1)/3)+1)*3)+1,1)-1 -> 44286 | E4: =DATE(YEAR(D4),((INT((MONTH(D4+3)-1)/3)+1)*3)+1,1)-1 -> 44377 | F4: =DATE(YEAR(E4),((INT((MONTH(E4+3)-1)/3)+1)*3)+1,1)-1 -> 44469 | G4: =DATE(YEAR(F4),((INT((MONTH(F4+3)-1)/3)+1)*3)+1,1)-1 -> 44561 | H4: =DATE(YEAR(G4+1),((INT((MONTH(G4+3)-1)/3)+1)*3)+1,1)-1 -> 44651 | I4: =DATE(YEAR(H4),((INT((MONTH(H4+3)-1)/3)+1)*3)+1,1)-1 -> 44742 | J4: =DATE(YEAR(I4),((INT((MONTH(I4+3)-1)/3)+1)*3)+1,1)-1 -> 44834 | K4: =DATE(YEAR(J4),((INT((MONTH(J4+3)-1)/3)+1)*3)+1,1)-1 -> 44926 | L4: =DATE(YEAR(K4+1),((INT((MONTH(K4+3)-1)/3)+1)*3)+1,1)-1 -> 45016 | M4: =DATE(YEAR(L4),((INT((MONTH(L4+3)-1)/3)+1)*3)+1,1)-1 -> 45107 | N4: =DATE(YEAR(M4),((INT((MONTH(M4+3)-1)/3)+1)*3)+1,1)-1 -> 45199 | O4: =DATE(YEAR(N4),((INT((MONTH(N4+3)-1)/3)+1)*3)+1,1)-1 -> 45291 | P4: =DATE(YEAR(O4+1),((INT((MONTH(O4+3)-1)/3)+1)*3)+1,1)-1 -> 45382 | Q4: =DATE(YEAR(P4),((INT((MONTH(P4+3)-1)/3)+1)*3)+1,1)-1 -> 45473 | R4: =DATE(YEAR(Q4),((INT((MONTH(Q4+3)-1)/3)+1)*3)+1,1)-1 -> 45565 | S4: =DATE(YEAR(R4),((INT((MONTH(R4+3)-1)/3)+1)*3)+1,1)-1 -> 45657 | T4: =DATE(YEAR(S4+1),((INT((MONTH(S4+3)-1)/3)+1)*3)+1,1)-1 -> 45747 | U4: =DATE(YEAR(T4),((INT((MONTH(T4+3)-1)/3)+1)*3)+1,1)-1 -> 45838 | V4: =DATE(YEAR(U4),((INT((MONTH(U4+3)-1)/3)+1)*3)+1,1)-1 -> 45930 | W4: =DATE(YEAR(V4),((INT((MONTH(V4+3)-1)/3)+1)*3)+1,1)-1 -> 46022 | X4: =DATE(YEAR(W4+1),((INT((MONTH(W4+3)-1)/3)+1)*3)+1,1)-1 -> 46112 | Y4: =DATE(YEAR(X4),((INT((MONTH(X4+3)-1)/3)+1)*3)+1,1)-1 -> 46203 | Z4: =DATE(YEAR(Y4),((INT((MONTH(Y4+3)-1)/3)+1)*3)+1,1)-1 -> 46295 | AA4: =DATE(YEAR(Z4),((INT((MONTH(Z4+3)-1)/3)+1)*3)+1,1)-1 -> 46387 | AB4: =DATE(YEAR(AA4+1),((INT((MONTH(AA4+3)-1)/3)+1)*3)+1,1)-1 -> 46477 | AC4: =DATE(YEAR(AB4),((INT((MONTH(AB4+3)-1)/3)+1)*3)+1,1)-1 -> 46568 | AD4: =DATE(YEAR(AC4),((INT((MONTH(AC4+3)-1)/3)+1)*3)+1,1)-1 -> 46660 | AE4: =DATE(YEAR(AD4),((INT((MONTH(AD4+3)-1)/3)+1)*3)+1,1)-1 -> 46752 | AF4: =DATE(YEAR(AE4+1),((INT((MONTH(AE4+3)-1)/3)+1)*3)+1,1)-1 -> 46843 | AG4: =DATE(YEAR(AF4),((INT((MONTH(AF4+3)-1)/3)+1)*3)+1,1)-1 -> 46934 | AH4: =DATE(YEAR(AG4),((INT((MONTH(AG4+3)-1)/3)+1)*3)+1,1)-1 -> 47026 | AI4: =DATE(YEAR(AH4),((INT((MONTH(AH4+3)-1)/3)+1)*3)+1,1)-1 -> 47118 | AJ4: =DATE(YEAR(AI4+1),((INT((MONTH(AI4+3)-1)/3)+1)*3)+1,1)-1 -> 47208 | AK4: =DATE(YEAR(AJ4),((INT((MONTH(AJ4+3)-1)/3)+1)*3)+1,1)-1 -> 47299 | AL4: =DATE(YEAR(AK4),((INT((MONTH(AK4+3)-1)/3)+1)*3)+1,1)-1 -> 47391 | AM4: =DATE(YEAR(AL4),((INT((MONTH(AL4+3)-1)/3)+1)*3)+1,1)-1 -> 47483 | AN4: =DATE(YEAR(AM4+1),((INT((MONTH(AM4+3)-1)/3)+1)*3)+1,1)-1 -> 47573 | AO4: =DATE(YEAR(AN4),((INT((MONTH(AN4+3)-1)/3)+1)*3)+1,1)-1 -> 47664 | AP4: =DATE(YEAR(AO4),((INT((MONTH(AO4+3)-1)/3)+1)*3)+1,1)-1 -> 47756 | AQ4: =DATE(YEAR(AP4),((INT((MONTH(AP4+3)-1)/3)+1)*3)+1,1)-1 -> 47848 | AR4: =DATE(YEAR(AQ4+1),((INT((MONTH(AQ4+3)-1)/3)+1)*3)+1,1)-1 -> 47938 | AS4: =DATE(YEAR(AR4),((INT((MONTH(AR4+3)-1)/3)+1)*3)+1,1)-1 -> 48029 | AT4: =DATE(YEAR(AS4),((INT((MONTH(AS4+3)-1)/3)+1)*3)+1,1)-1 -> 48121 | AU4: =DATE(YEAR(AT4),((INT((MONTH(AT4+3)-1)/3)+1)*3)+1,1)-1 -> 48213
B5: Fund | C5: ='Summary and Assumptions'!D11 -> 100000000 | D5: Q1 E | E5: Q2 E | F5: Q3 E | G5: Q4 E | H5: Q1 E | I5: Q2 E | J5: Q3 E | K5: Q4 E | L5: Q1 E | M5: Q2 E | N5: Q3 E | O5: Q4 E | P5: Q1 E | Q5: Q2 E | R5: Q3 E | S5: Q4 E | T5: Q1 E | U5: Q2 E | V5: Q3 E | W5: Q4 E | X5: Q1 E | Y5: Q2 E | Z5: Q3 E | AA5: Q4 E | AB5: Q1 E | AC5: Q2 E | AD5: Q3 E | AE5: Q4 E | AF5: Q1 E | AG5: Q2 E | AH5: Q3 E | AI5: Q4 E | AJ5: Q1 E | AK5: Q2 E | AL5: Q3 E | AM5: Q4 E | AN5: Q1 E | AO5: Q2 E | AP5: Q3 E | AQ5: Q4 E | AR5: Q1 E | AS5: Q2 E | AT5: Q3 E | AU5: Q4 E
A6: Cash Flow Model
A8: x | B8: Investments
B9: =IF(Portfolio!C7<>"",Portfolio!C7,"") -> 1 | C9: =IF(Portfolio!D7<>"",Portfolio!D7,"") -> Company 1 | D9: =SUMPRODUCT((Portfolio!$F$7:$J$7=D$4)*(Portfolio!$F$9:$J$9)) -> 1250000 | E9: =SUMPRODUCT((Portfolio!$F$7:$J$7=E$4)*(Portfolio!$F$9:$J$9)) -> 0 | F9: =SUMPRODUCT((Portfolio!$F$7:$J$7=F$4)*(Portfolio!$F$9:$J$9)) -> 0 | G9: =SUMPRODUCT((Portfolio!$F$7:$J$7=G$4)*(Portfolio!$F$9:$J$9)) -> 0 | H9: =SUMPRODUCT((Portfolio!$F$7:$J$7=H$4)*(Portfolio!$F$9:$J$9)) -> 0 | I9: =SUMPRODUCT((Portfolio!$F$7:$J$7=I$4)*(Portfolio!$F$9:$J$9)) -> 112500 | J9: =SUMPRODUCT((Portfolio!$F$7:$J$7=J$4)*(Portfolio!$F$9:$J$9)) -> 937500 | K9: =SUMPRODUCT((Portfolio!$F$7:$J$7=K$4)*(Portfolio!$F$9:$J$9)) -> 0 | ... AU9: =SUMPRODUCT((Portfolio!$F$7:$J$7=AU$4)*(Portfolio!$F$9:$J$9)) -> 0
B10: =IF(Portfolio!C10<>"",Portfolio!C10,"") -> 2 | C10: =IF(Portfolio!D10<>"",Portfolio!D10,"") -> Company 2 | D10: =SUMPRODUCT((Portfolio!$F$10:$J$10=D$4)*(Portfolio!$F$12:$J$12)) -> 1250000 | E10: =SUMPRODUCT((Portfolio!$F$10:$J$10=E$4)*(Portfolio!$F$12:$J$12)) -> 0 | F10: =SUMPRODUCT((Portfolio!$F$10:$J$10=F$4)*(Portfolio!$F$12:$J$12)) -> 0 | G10: =SUMPRODUCT((Portfolio!$F$10:$J$10=G$4)*(Portfolio!$F$12:$J$12)) -> 0 | H10: =SUMPRODUCT((Portfolio!$F$10:$J$10=H$4)*(Portfolio!$F$12:$J$12)) -> 0 | I10: =SUMPRODUCT((Portfolio!$F$10:$J$10=I$4)*(Portfolio!$F$12:$J$12)) -> 112500 | J10: =SUMPRODUCT((Portfolio!$F$10:$J$10=J$4)*(Portfolio!$F$12:$J$12)) -> 937500 | K10: =SUMPRODUCT((Portfolio!$F$10:$J$10=K$4)*(Portfolio!$F$12:$J$12)) -> 0 | ... AU10: =SUMPRODUCT((Portfolio!$F$10:$J$10=AU$4)*(Portfolio!$F$12:$J$12)) -> 0
B11: =IF(Portfolio!C13<>"",Portfolio!C13,"") -> 3 | C11: =IF(Portfolio!D13<>"",Portfolio!D13,"") -> Company 3 | D11: =SUMPRODUCT((Portfolio!$F$13:$J$13=D$4)*(Portfolio!$F$15:$J$15)) -> 0 | E11: =SUMPRODUCT((Portfolio!$F$13:$J$13=E$4)*(Portfolio!$F$15:$J$15)) -> 1250000 | F11: =SUMPRODUCT((Portfolio!$F$13:$J$13=F$4)*(Portfolio!$F$15:$J$15)) -> 0 | G11: =SUMPRODUCT((Portfolio!$F$13:$J$13=G$4)*(Portfolio!$F$15:$J$15)) -> 0 | H11: =SUMPRODUCT((Portfolio!$F$13:$J$13=H$4)*(Portfolio!$F$15:$J$15)) -> 0 | I11: =SUMPRODUCT((Portfolio!$F$13:$J$13=I$4)*(Portfolio!$F$15:$J$15)) -> 0 | J11: =SUMPRODUCT((Portfolio!$F$13:$J$13=J$4)*(Portfolio!$F$15:$J$15)) -> 1050000 | K11: =SUMPRODUCT((Portfolio!$F$13:$J$13=K$4)*(Portfolio!$F$15:$J$15)) -> 0 | ... AU11: =SUMPRODUCT((Portfolio!$F$13:$J$13=AU$4)*(Portfolio!$F$15:$J$15)) -> 0
B12: =IF(Portfolio!C16<>"",Portfolio!C16,"") -> 4 | C12: =IF(Portfolio!D16<>"",Portfolio!D16,"") -> Company 4 | D12: =SUMPRODUCT((Portfolio!$F$16:$J$16=D$4)*(Portfolio!$F$18:$J$18)) -> 0 | E12: =SUMPRODUCT((Portfolio!$F$16:$J$16=E$4)*(Portfolio!$F$18:$J$18)) -> 1250000 | F12: =SUMPRODUCT((Portfolio!$F$16:$J$16=F$4)*(Portfolio!$F$18:$J$18)) -> 0 | G12: =SUMPRODUCT((Portfolio!$F$16:$J$16=G$4)*(Portfolio!$F$18:$J$18)) -> 0 | H12: =SUMPRODUCT((Portfolio!$F$16:$J$16=H$4)*(Portfolio!$F$18:$J$18)) -> 0 | I12: =SUMPRODUCT((Portfolio!$F$16:$J$16=I$4)*(Portfolio!$F$18:$J$18)) -> 0 | J12: =SUMPRODUCT((Portfolio!$F$16:$J$16=J$4)*(Portfolio!$F$18:$J$18)) -> 112500 | K12: =SUMPRODUCT((Portfolio!$F$16:$J$16=K$4)*(Portfolio!$F$18:$J$18)) -> 937500 | ... AU12: =SUMPRODUCT((Portfolio!$F$16:$J$16=AU$4)*(Portfolio!$F$18:$J$18)) -> 0
B13: =IF(Portfolio!C19<>"",Portfolio!C19,"") -> 5 | C13: =IF(Portfolio!D19<>"",Portfolio!D19,"") -> Company 5 | D13: =SUMPRODUCT((Portfolio!$F19:$J19=D$4)*(Portfolio!$F21:$J21)) -> 0 | E13: =SUMPRODUCT((Portfolio!$F19:$J19=E$4)*(Portfolio!$F21:$J21)) -> 1250000 | F13: =SUMPRODUCT((Portfolio!$F19:$J19=F$4)*(Portfolio!$F21:$J21)) -> 0 | G13: =SUMPRODUCT((Portfolio!$F19:$J19=G$4)*(Portfolio!$F21:$J21)) -> 0 | H13: =SUMPRODUCT((Portfolio!$F19:$J19=H$4)*(Portfolio!$F21:$J21)) -> 0 | I13: =SUMPRODUCT((Portfolio!$F19:$J19=I$4)*(Portfolio!$F21:$J21)) -> 0 | J13: =SUMPRODUCT((Portfolio!$F19:$J19=J$4)*(Portfolio!$F21:$J21)) -> 112500 | K13: =SUMPRODUCT((Portfolio!$F19:$J19=K$4)*(Portfolio!$F21:$J21)) -> 937500 | ... AU13: =SUMPRODUCT((Portfolio!$F19:$J19=AU$4)*(Portfolio!$F21:$J21)) -> 0
B14: =IF(Portfolio!C22<>"",Portfolio!C22,"") -> 6 | C14: =IF(Portfolio!D22<>"",Portfolio!D22,"") -> Company 6 | D14: =SUMPRODUCT((Portfolio!$F22:$J22=D$4)*(Portfolio!$F24:$J24)) -> 0 | E14: =SUMPRODUCT((Portfolio!$F22:$J22=E$4)*(Portfolio!$F24:$J24)) -> 0 | F14: =SUMPRODUCT((Portfolio!$F22:$J22=F$4)*(Portfolio!$F24:$J24)) -> 1250000 | G14: =SUMPRODUCT((Portfolio!$F22:$J22=G$4)*(Portfolio!$F24:$J24)) -> 0 | H14: =SUMPRODUCT((Portfolio!$F22:$J22=H$4)*(Portfolio!$F24:$J24)) -> 0 | I14: =SUMPRODUCT((Portfolio!$F22:$J22=I$4)*(Portfolio!$F24:$J24)) -> 0 | J14: =SUMPRODUCT((Portfolio!$F22:$J22=J$4)*(Portfolio!$F24:$J24)) -> 0 | K14: =SUMPRODUCT((Portfolio!$F22:$J22=K$4)*(Portfolio!$F24:$J24)) -> 112500 | ... AU14: =SUMPRODUCT((Portfolio!$F22:$J22=AU$4)*(Portfolio!$F24:$J24)) -> 0
B15: =IF(Portfolio!C25<>"",Portfolio!C25,"") -> 7 | C15: =IF(Portfolio!D25<>"",Portfolio!D25,"") -> Company 7 | D15: =SUMPRODUCT((Portfolio!$F25:$J25=D$4)*(Portfolio!$F27:$J27)) -> 0 | E15: =SUMPRODUCT((Portfolio!$F25:$J25=E$4)*(Portfolio!$F27:$J27)) -> 0 | F15: =SUMPRODUCT((Portfolio!$F25:$J25=F$4)*(Portfolio!$F27:$J27)) -> 1250000 | G15: =SUMPRODUCT((Portfolio!$F25:$J25=G$4)*(Portfolio!$F27:$J27)) -> 0 | H15: =SUMPRODUCT((Portfolio!$F25:$J25=H$4)*(Portfolio!$F27:$J27)) -> 0 | I15: =SUMPRODUCT((Portfolio!$F25:$J25=I$4)*(Portfolio!$F27:$J27)) -> 0 | J15: =SUMPRODUCT((Portfolio!$F25:$J25=J$4)*(Portfolio!$F27:$J27)) -> 0 | K15: =SUMPRODUCT((Portfolio!$F25:$J25=K$4)*(Portfolio!$F27:$J27)) -> 112500 | ... AU15: =SUMPRODUCT((Portfolio!$F25:$J25=AU$4)*(Portfolio!$F27:$J27)) -> 0
B16: =IF(Portfolio!C28<>"",Portfolio!C28,"") -> 8 | C16: =IF(Portfolio!D28<>"",Portfolio!D28,"") -> Company 8 | D16: =SUMPRODUCT((Portfolio!$F28:$J28=D$4)*(Portfolio!$F30:$J30)) -> 0 | E16: =SUMPRODUCT((Portfolio!$F28:$J28=E$4)*(Portfolio!$F30:$J30)) -> 0 | F16: =SUMPRODUCT((Portfolio!$F28:$J28=F$4)*(Portfolio!$F30:$J30)) -> 0 | G16: =SUMPRODUCT((Portfolio!$F28:$J28=G$4)*(Portfolio!$F30:$J30)) -> 1250000 | H16: =SUMPRODUCT((Portfolio!$F28:$J28=H$4)*(Portfolio!$F30:$J30)) -> 0 | I16: =SUMPRODUCT((Portfolio!$F28:$J28=I$4)*(Portfolio!$F30:$J30)) -> 0 | J16: =SUMPRODUCT((Portfolio!$F28:$J28=J$4)*(Portfolio!$F30:$J30)) -> 0 | K16: =SUMPRODUCT((Portfolio!$F28:$J28=K$4)*(Portfolio!$F30:$J30)) -> 0 | ... AU16: =SUMPRODUCT((Portfolio!$F28:$J28=AU$4)*(Portfolio!$F30:$J30)) -> 0
B17: =IF(Portfolio!C31<>"",Portfolio!C31,"") -> 9 | C17: =IF(Portfolio!D31<>"",Portfolio!D31,"") -> Company 9 | D17: =SUMPRODUCT((Portfolio!$F31:$J31=D$4)*(Portfolio!$F33:$J33)) -> 0 | E17: =SUMPRODUCT((Portfolio!$F31:$J31=E$4)*(Portfolio!$F33:$J33)) -> 0 | F17: =SUMPRODUCT((Portfolio!$F31:$J31=F$4)*(Portfolio!$F33:$J33)) -> 0 | G17: =SUMPRODUCT((Portfolio!$F31:$J31=G$4)*(Portfolio!$F33:$J33)) -> 1250000 | H17: =SUMPRODUCT((Portfolio!$F31:$J31=H$4)*(Portfolio!$F33:$J33)) -> 0 | I17: =SUMPRODUCT((Portfolio!$F31:$J31=I$4)*(Portfolio!$F33:$J33)) -> 0 | J17: =SUMPRODUCT((Portfolio!$F31:$J31=J$4)*(Portfolio!$F33:$J33)) -> 0 | K17: =SUMPRODUCT((Portfolio!$F31:$J31=K$4)*(Portfolio!$F33:$J33)) -> 0 | ... AU17: =SUMPRODUCT((Portfolio!$F31:$J31=AU$4)*(Portfolio!$F33:$J33)) -> 0
B18: =IF(Portfolio!C34<>"",Portfolio!C34,"") -> 10 | C18: =IF(Portfolio!D34<>"",Portfolio!D34,"") -> Company 10 | D18: =SUMPRODUCT((Portfolio!$F34:$J34=D$4)*(Portfolio!$F36:$J36)) -> 0 | E18: =SUMPRODUCT((Portfolio!$F34:$J34=E$4)*(Portfolio!$F36:$J36)) -> 0 | F18: =SUMPRODUCT((Portfolio!$F34:$J34=F$4)*(Portfolio!$F36:$J36)) -> 0 | G18: =SUMPRODUCT((Portfolio!$F34:$J34=G$4)*(Portfolio!$F36:$J36)) -> 1250000 | H18: =SUMPRODUCT((Portfolio!$F34:$J34=H$4)*(Portfolio!$F36:$J36)) -> 0 | I18: =SUMPRODUCT((Portfolio!$F34:$J34=I$4)*(Portfolio!$F36:$J36)) -> 0 | J18: =SUMPRODUCT((Portfolio!$F34:$J34=J$4)*(Portfolio!$F36:$J36)) -> 0 | K18: =SUMPRODUCT((Portfolio!$F34:$J34=K$4)*(Portfolio!$F36:$J36)) -> 0 | ... AU18: =SUMPRODUCT((Portfolio!$F34:$J34=AU$4)*(Portfolio!$F36:$J36)) -> 0
B19: =IF(Portfolio!C37<>"",Portfolio!C37,"") -> 11 | C19: =IF(Portfolio!D37<>"",Portfolio!D37,"") -> Company 11 | D19: =SUMPRODUCT((Portfolio!$F37:$J37=D$4)*(Portfolio!$F39:$J39)) -> 0 | E19: =SUMPRODUCT((Portfolio!$F37:$J37=E$4)*(Portfolio!$F39:$J39)) -> 0 | F19: =SUMPRODUCT((Portfolio!$F37:$J37=F$4)*(Portfolio!$F39:$J39)) -> 0 | G19: =SUMPRODUCT((Portfolio!$F37:$J37=G$4)*(Portfolio!$F39:$J39)) -> 0 | H19: =SUMPRODUCT((Portfolio!$F37:$J37=H$4)*(Portfolio!$F39:$J39)) -> 1250000 | I19: =SUMPRODUCT((Portfolio!$F37:$J37=I$4)*(Portfolio!$F39:$J39)) -> 0 | J19: =SUMPRODUCT((Portfolio!$F37:$J37=J$4)*(Portfolio!$F39:$J39)) -> 0 | K19: =SUMPRODUCT((Portfolio!$F37:$J37=K$4)*(Portfolio!$F39:$J39)) -> 0 | ... AU19: =SUMPRODUCT((Portfolio!$F37:$J37=AU$4)*(Portfolio!$F39:$J39)) -> 0
B20: =IF(Portfolio!C40<>"",Portfolio!C40,"") -> 12 | C20: =IF(Portfolio!D40<>"",Portfolio!D40,"") -> Company 12 | D20: =SUMPRODUCT((Portfolio!$F40:$J40=D$4)*(Portfolio!$F42:$J42)) -> 0 | E20: =SUMPRODUCT((Portfolio!$F40:$J40=E$4)*(Portfolio!$F42:$J42)) -> 0 | F20: =SUMPRODUCT((Portfolio!$F40:$J40=F$4)*(Portfolio!$F42:$J42)) -> 0 | G20: =SUMPRODUCT((Portfolio!$F40:$J40=G$4)*(Portfolio!$F42:$J42)) -> 0 | H20: =SUMPRODUCT((Portfolio!$F40:$J40=H$4)*(Portfolio!$F42:$J42)) -> 1250000 | I20: =SUMPRODUCT((Portfolio!$F40:$J40=I$4)*(Portfolio!$F42:$J42)) -> 0 | J20: =SUMPRODUCT((Portfolio!$F40:$J40=J$4)*(Portfolio!$F42:$J42)) -> 0 | K20: =SUMPRODUCT((Portfolio!$F40:$J40=K$4)*(Portfolio!$F42:$J42)) -> 0 | ... AU20: =SUMPRODUCT((Portfolio!$F40:$J40=AU$4)*(Portfolio!$F42:$J42)) -> 0
B21: =IF(Portfolio!C43<>"",Portfolio!C43,"") -> 13 | C21: =IF(Portfolio!D43<>"",Portfolio!D43,"") -> Company 13 | D21: =SUMPRODUCT((Portfolio!$F43:$J43=D$4)*(Portfolio!$F45:$J45)) -> 0 | E21: =SUMPRODUCT((Portfolio!$F43:$J43=E$4)*(Portfolio!$F45:$J45)) -> 0 | F21: =SUMPRODUCT((Portfolio!$F43:$J43=F$4)*(Portfolio!$F45:$J45)) -> 0 | G21: =SUMPRODUCT((Portfolio!$F43:$J43=G$4)*(Portfolio!$F45:$J45)) -> 0 | H21: =SUMPRODUCT((Portfolio!$F43:$J43=H$4)*(Portfolio!$F45:$J45)) -> 0 | I21: =SUMPRODUCT((Portfolio!$F43:$J43=I$4)*(Portfolio!$F45:$J45)) -> 1250000 | J21: =SUMPRODUCT((Portfolio!$F43:$J43=J$4)*(Portfolio!$F45:$J45)) -> 0 | K21: =SUMPRODUCT((Portfolio!$F43:$J43=K$4)*(Portfolio!$F45:$J45)) -> 0 | ... AU21: =SUMPRODUCT((Portfolio!$F43:$J43=AU$4)*(Portfolio!$F45:$J45)) -> 0
B22: =IF(Portfolio!C46<>"",Portfolio!C46,"") -> 14 | C22: =IF(Portfolio!D46<>"",Portfolio!D46,"") -> Company 14 | D22: =SUMPRODUCT((Portfolio!$F46:$J46=D$4)*(Portfolio!$F48:$J48)) -> 0 | E22: =SUMPRODUCT((Portfolio!$F46:$J46=E$4)*(Portfolio!$F48:$J48)) -> 0 | F22: =SUMPRODUCT((Portfolio!$F46:$J46=F$4)*(Portfolio!$F48:$J48)) -> 0 | G22: =SUMPRODUCT((Portfolio!$F46:$J46=G$4)*(Portfolio!$F48:$J48)) -> 0 | H22: =SUMPRODUCT((Portfolio!$F46:$J46=H$4)*(Portfolio!$F48:$J48)) -> 0 | I22: =SUMPRODUCT((Portfolio!$F46:$J46=I$4)*(Portfolio!$F48:$J48)) -> 1250000 | J22: =SUMPRODUCT((Portfolio!$F46:$J46=J$4)*(Portfolio!$F48:$J48)) -> 0 | K22: =SUMPRODUCT((Portfolio!$F46:$J46=K$4)*(Portfolio!$F48:$J48)) -> 0 | ... AU22: =SUMPRODUCT((Portfolio!$F46:$J46=AU$4)*(Portfolio!$F48:$J48)) -> 0
B23: =IF(Portfolio!C49<>"",Portfolio!C49,"") -> 15 | C23: =IF(Portfolio!D49<>"",Portfolio!D49,"") -> Company 15 | D23: =SUMPRODUCT((Portfolio!$F49:$J49=D$4)*(Portfolio!$F51:$J51)) -> 0 | E23: =SUMPRODUCT((Portfolio!$F49:$J49=E$4)*(Portfolio!$F51:$J51)) -> 0 | F23: =SUMPRODUCT((Portfolio!$F49:$J49=F$4)*(Portfolio!$F51:$J51)) -> 0 | G23: =SUMPRODUCT((Portfolio!$F49:$J49=G$4)*(Portfolio!$F51:$J51)) -> 0 | H23: =SUMPRODUCT((Portfolio!$F49:$J49=H$4)*(Portfolio!$F51:$J51)) -> 0 | I23: =SUMPRODUCT((Portfolio!$F49:$J49=I$4)*(Portfolio!$F51:$J51)) -> 1250000 | J23: =SUMPRODUCT((Portfolio!$F49:$J49=J$4)*(Portfolio!$F51:$J51)) -> 0 | K23: =SUMPRODUCT((Portfolio!$F49:$J49=K$4)*(Portfolio!$F51:$J51)) -> 0 | ... AU23: =SUMPRODUCT((Portfolio!$F49:$J49=AU$4)*(Portfolio!$F51:$J51)) -> 0
B24: =IF(Portfolio!C52<>"",Portfolio!C52,"") -> 16 | C24: =IF(Portfolio!D52<>"",Portfolio!D52,"") -> Company 16 | D24: =SUMPRODUCT((Portfolio!$F52:$J52=D$4)*(Portfolio!$F54:$J54)) -> 0 | E24: =SUMPRODUCT((Portfolio!$F52:$J52=E$4)*(Portfolio!$F54:$J54)) -> 0 | F24: =SUMPRODUCT((Portfolio!$F52:$J52=F$4)*(Portfolio!$F54:$J54)) -> 0 | G24: =SUMPRODUCT((Portfolio!$F52:$J52=G$4)*(Portfolio!$F54:$J54)) -> 0 | H24: =SUMPRODUCT((Portfolio!$F52:$J52=H$4)*(Portfolio!$F54:$J54)) -> 0 | I24: =SUMPRODUCT((Portfolio!$F52:$J52=I$4)*(Portfolio!$F54:$J54)) -> 0 | J24: =SUMPRODUCT((Portfolio!$F52:$J52=J$4)*(Portfolio!$F54:$J54)) -> 1250000 | K24: =SUMPRODUCT((Portfolio!$F52:$J52=K$4)*(Portfolio!$F54:$J54)) -> 0 | ... AU24: =SUMPRODUCT((Portfolio!$F52:$J52=AU$4)*(Portfolio!$F54:$J54)) -> 0
